Workbook
Name Areas: 'Config'!$B$15:$B$214
Name Activities: 'Config'!$C$15:$C$214
Name Agencies: 'Config'!$D$15:$D$214

Sheet READ ME
B2: JSW UTKAL STEEL — DAILY PROGRESS REPORT (consolidation workbook)
B4: HOW THE PIECES FIT TOGETHER
B5: 1. dpr_consolidator.html — open it in Chrome/Edge. Drop in every vendor DPR you receive
B6: (any layout, .xlsx / .xls / .csv). It auto-detects the header row, maps the vendor's
B7: column names to this format, matches each line to your master scope, and exports the
B8: finished DPR in exactly the format of this workbook.
B9: 2. This workbook — the approved format. Use it as (a) the master-scope source you load into
B10: the HTML tool, and (b) the manual fallback if you would rather type the numbers in.
B12: SHEETS
B13: Config Project title, data date, reporting date, and the master drop-down lists.
B14: Summary-AreaWise The printed summary. Every number is a SUMIFS() pulled from the backup
B15: sheets. Fill only the green columns (Activity, Agency) plus the two grey
... B41: Activity as columns the formulas address whole columns and never need maintenance.

Sheet Summary-AreaWise
B2: JSW | C2: =Config!$C$5
C3: =Config!$C$4
J4: Data date: | K4: =Config!$C$6
J5: Reporting date: | K5: =Config!$C$7
B6: SI No. | C6: Area / Activities | D6: Agency / Contractor | E6: Scope | F6: Drawing Released | G6: Front Available | H6: Workdone Till Date | I6: % Complete | J6: Balance | K6: ="Plan for "&Config!$C$8 | L6: ="Achieved for "&Config!$C$8 | M6: Achieved FTD | N6: Available Manpower | P6: Area (helper) | Q6: Source sheet (helper)
B7: a | C7: b | D7: c | E7: d | F7: e | G7: f | H7: g | I7: h = (g/d)x100 | J7: i = d-g | K7: j | L7: k | M7: l | N7: m
B8: =IF(OR($C8="",$Q8=""),"",COUNTA($C$8:$C8)) | E8: =IF(OR($C8="",$Q8=""),"",IFERROR(SUMIFS(INDIRECT("'"&$Q8&"'!$G$9:$G$408"),INDIRECT("'"&$Q8&"'!$D$9:$D$408"),$P8,INDIRECT("'"&$Q8&"'!$E$9:$E$408"),$C8,INDIRECT("'"&$Q8&"'!$F$9:$F$408"),$D8),"")) | F8: =IF(OR($C8="",$Q8=""),"",IFERROR(SUMIFS(INDIRECT("'"&$Q8&"'!$H$9:$H$408"),INDIRECT("'"&$Q8&"'!$D$9:$D$408"),$P8,INDIRECT("'"&$Q8&"'!$E$9:$E$408"),$C8,INDIRECT("'"&$Q8&"'!$F$9:$F$408"),$D8),"")) | G8: =IF(OR($C8="",$Q8=""),"",IFERROR(SUMIFS(INDIRECT("'"&$Q8&"'!$I$9:$I$408"),INDIRECT("'"&$Q8&"'!$D$9:$D$408"),$P8,INDIRECT("'"&$Q8&"'!$E$9:$E$408"),$C8,INDIRECT("'"&$Q8&"'!$F$9:$F$408"),$D8),"")) | H8: =IF(OR($C8="",$Q8=""),"",IFERROR(SUMIFS(INDIRECT("'"&$Q8&"'!$R$9:$R$408"),INDIRECT("'"&$Q8&"'!$D$9:$D$408"),$P8,INDIRECT("'"&$Q8&"'!$E$9:$E$408"),$C8,INDIRECT("'"&$Q8&"'!$F$9:$F$408"),$D8),"")) | I8: =IF(OR(OR($C8="",$Q8=""),N(E8)=0),"",H8/E8) | J8: =IF(OR($C8="",$Q8=""),"",N(E8)-N(H8)) | K8: =IF(OR($C8="",$Q8=""),"",IFERROR(SUMIFS(INDIRECT("'"&$Q8&"'!$K$9:$K$408"),INDIRECT("'"&$Q8&"'!$D$9:$D$408"),$P8,INDIRECT("'"&$Q8&"'!$E$9:$E$408"),$C8,INDIRECT("'"&$Q8&"'!$F$9:$F$408"),$D8),"")) | L8: =IF(OR($C8="",$Q8=""),"",IFERROR(SUMIFS(INDIRECT("'"&$Q8&"'!$Q$9:$Q$408"),INDIRECT("'"&$Q8&"'!$D$9:$D$408"),$P8,INDIRECT("'"&$Q8&"'!$E$9:$E$408"),$C8,INDIRECT("'"&$Q8&"'!$F$9:$F$408"),$D8),"")) | M8: =IF(OR($C8="",$Q8=""),"",IFERROR(SUMIFS(INDIRECT("'"&$Q8&"'!$M$9:$M$408"),INDIRECT("'"&$Q8&"'!$D$9:$D$408"),$P8,INDIRECT("'"&$Q8&"'!$E$9:$E$408"),$C8,INDIRECT("'"&$Q8&"'!$F$9:$F$408"),$D8),"")) | N8: =IF(OR($C8="",$Q8=""),"",IFERROR(SUMIFS(INDIRECT("'"&$Q8&"'!$V$9:$V$408"),INDIRECT("'"&$Q8&"'!$D$9:$D$408"),$P8,INDIRECT("'"&$Q8&"'!$E$9:$E$408"),$C8,INDIRECT("'"&$Q8&"'!$F$9:$F$408"),$D8),""))
B9: =IF(OR($C9="",$Q9=""),"",COUNTA($C$8:$C9)) | E9: =IF(OR($C9="",$Q9=""),"",IFERROR(SUMIFS(INDIRECT("'"&$Q9&"'!$G$9:$G$408"),INDIRECT("'"&$Q9&"'!$D$9:$D$408"),$P9,INDIRECT("'"&$Q9&"'!$E$9:$E$408"),$C9,INDIRECT("'"&$Q9&"'!$F$9:$F$408"),$D9),"")) | F9: =IF(OR($C9="",$Q9=""),"",IFERROR(SUMIFS(INDIRECT("'"&$Q9&"'!$H$9:$H$408"),INDIRECT("'"&$Q9&"'!$D$9:$D$408"),$P9,INDIRECT("'"&$Q9&"'!$E$9:$E$408"),$C9,INDIRECT("'"&$Q9&"'!$F$9:$F$408"),$D9),"")) | G9: =IF(OR($C9="",$Q9=""),"",IFERROR(SUMIFS(INDIRECT("'"&$Q9&"'!$I$9:$I$408"),INDIRECT("'"&$Q9&"'!$D$9:$D$408"),$P9,INDIRECT("'"&$Q9&"'!$E$9:$E$408"),$C9,INDIRECT("'"&$Q9&"'!$F$9:$F$408"),$D9),"")) | H9: =IF(OR($C9="",$Q9=""),"",IFERROR(SUMIFS(INDIRECT("'"&$Q9&"'!$R$9:$R$408"),INDIRECT("'"&$Q9&"'!$D$9:$D$408"),$P9,INDIRECT("'"&$Q9&"'!$E$9:$E$408"),$C9,INDIRECT("'"&$Q9&"'!$F$9:$F$408"),$D9),"")) | I9: =IF(OR(OR($C9="",$Q9=""),N(E9)=0),"",H9/E9) | J9: =IF(OR($C9="",$Q9=""),"",N(E9)-N(H9)) | K9: =IF(OR($C9="",$Q9=""),"",IFERROR(SUMIFS(INDIRECT("'"&$Q9&"'!$K$9:$K$408"),INDIRECT("'"&$Q9&"'!$D$9:$D$408"),$P9,INDIRECT("'"&$Q9&"'!$E$9:$E$408"),$C9,INDIRECT("'"&$Q9&"'!$F$9:$F$408"),$D9),"")) | L9: =IF(OR($C9="",$Q9=""),"",IFERROR(SUMIFS(INDIRECT("'"&$Q9&"'!$Q$9:$Q$408"),INDIRECT("'"&$Q9&"'!$D$9:$D$408"),$P9,INDIRECT("'"&$Q9&"'!$E$9:$E$408"),$C9,INDIRECT("'"&$Q9&"'!$F$9:$F$408"),$D9),"")) | M9: =IF(OR($C9="",$Q9=""),"",IFERROR(SUMIFS(INDIRECT("'"&$Q9&"'!$M$9:$M$408"),INDIRECT("'"&$Q9&"'!$D$9:$D$408"),$P9,INDIRECT("'"&$Q9&"'!$E$9:$E$408"),$C9,INDIRECT("'"&$Q9&"'!$F$9:$F$408"),$D9),"")) | N9: =IF(OR($C9="",$Q9=""),"",IFERROR(SUMIFS(INDIRECT("'"&$Q9&"'!$V$9:$V$408"),INDIRECT("'"&$Q9&"'!$D$9:$D$408"),$P9,INDIRECT("'"&$Q9&"'!$E$9:$E$408"),$C9,INDIRECT("'"&$Q9&"'!$F$9:$F$408"),$D9),""))
B10: =IF(OR($C10="",$Q10=""),"",COUNTA($C$8:$C10)) | E10: =IF(OR($C10="",$Q10=""),"",IFERROR(SUMIFS(INDIRECT("'"&$Q10&"'!$G$9:$G$408"),INDIRECT("'"&$Q10&"'!$D$9:$D$408"),$P10,INDIRECT("'"&$Q10&"'!$E$9:$E$408"),$C10,INDIRECT("'"&$Q10&"'!$F$9:$F$408"),$D10),"")) | F10: =IF(OR($C10="",$Q10=""),"",IFERROR(SUMIFS(INDIRECT("'"&$Q10&"'!$H$9:$H$408"),INDIRECT("'"&$Q10&"'!$D$9:$D$408"),$P10,INDIRECT("'"&$Q10&"'!$E$9:$E$408"),$C10,INDIRECT("'"&$Q10&"'!$F$9:$F$408"),$D10),"")) | G10: =IF(OR($C10="",$Q10=""),"",IFERROR(SUMIFS(INDIRECT("'"&$Q10&"'!$I$9:$I$408"),INDIRECT("'"&$Q10&"'!$D$9:$D$408"),$P10,INDIRECT("'"&$Q10&"'!$E$9:$E$408"),$C10,INDIRECT("'"&$Q10&"'!$F$9:$F$408"),$D10),"")) | H10: =IF(OR($C10="",$Q10=""),"",IFERROR(SUMIFS(INDIRECT("'"&$Q10&"'!$R$9:$R$408"),INDIRECT("'"&$Q10&"'!$D$9:$D$408"),$P10,INDIRECT("'"&$Q10&"'!$E$9:$E$408"),$C10,INDIRECT("'"&$Q10&"'!$F$9:$F$408"),$D10),"")) | I10: =IF(OR(OR($C10="",$Q10=""),N(E10)=0),"",H10/E10) | J10: =IF(OR($C10="",$Q10=""),"",N(E10)-N(H10)) | K10: =IF(OR($C10="",$Q10=""),"",IFERROR(SUMIFS(INDIRECT("'"&$Q10&"'!$K$9:$K$408"),INDIRECT("'"&$Q10&"'!$D$9:$D$408"),$P10,INDIRECT("'"&$Q10&"'!$E$9:$E$408"),$C10,INDIRECT("'"&$Q10&"'!$F$9:$F$408"),$D10),"")) | L10: =IF(OR($C10="",$Q10=""),"",IFERROR(SUMIFS(INDIRECT("'"&$Q10&"'!$Q$9:$Q$408"),INDIRECT("'"&$Q10&"'!$D$9:$D$408"),$P10,INDIRECT("'"&$Q10&"'!$E$9:$E$408"),$C10,INDIRECT("'"&$Q10&"'!$F$9:$F$408"),$D10),"")) | M10: =IF(OR($C10="",$Q10=""),"",IFERROR(SUMIFS(INDIRECT("'"&$Q10&"'!$M$9:$M$408"),INDIRECT("'"&$Q10&"'!$D$9:$D$408"),$P10,INDIRECT("'"&$Q10&"'!$E$9:$E$408"),$C10,INDIRECT("'"&$Q10&"'!$F$9:$F$408"),$D10),"")) | N10: =IF(OR($C10="",$Q10=""),"",IFERROR(SUMIFS(INDIRECT("'"&$Q10&"'!$V$9:$V$408"),INDIRECT("'"&$Q10&"'!$D$9:$D$408"),$P10,INDIRECT("'"&$Q10&"'!$E$9:$E$408"),$C10,INDIRECT("'"&$Q10&"'!$F$9:$F$408"),$D10),""))
B11: =IF(OR($C11="",$Q11=""),"",COUNTA($C$8:$C11)) | E11: =IF(OR($C11="",$Q11=""),"",IFERROR(SUMIFS(INDIRECT("'"&$Q11&"'!$G$9:$G$408"),INDIRECT("'"&$Q11&"'!$D$9:$D$408"),$P11,INDIRECT("'"&$Q11&"'!$E$9:$E$408"),$C11,INDIRECT("'"&$Q11&"'!$F$9:$F$408"),$D11),"")) | F11: =IF(OR($C11="",$Q11=""),"",IFERROR(SUMIFS(INDIRECT("'"&$Q11&"'!$H$9:$H$408"),INDIRECT("'"&$Q11&"'!$D$9:$D$408"),$P11,INDIRECT("'"&$Q11&"'!$E$9:$E$408"),$C11,INDIRECT("'"&$Q11&"'!$F$9:$F$408"),$D11),"")) | G11: =IF(OR($C11="",$Q11=""),"",IFERROR(SUMIFS(INDIRECT("'"&$Q11&"'!$I$9:$I$408"),INDIRECT("'"&$Q11&"'!$D$9:$D$408"),$P11,INDIRECT("'"&$Q11&"'!$E$9:$E$408"),$C11,INDIRECT("'"&$Q11&"'!$F$9:$F$408"),$D11),"")) | H11: =IF(OR($C11="",$Q11=""),"",IFERROR(SUMIFS(INDIRECT("'"&$Q11&"'!$R$9:$R$408"),INDIRECT("'"&$Q11&"'!$D$9:$D$408"),$P11,INDIRECT("'"&$Q11&"'!$E$9:$E$408"),$C11,INDIRECT("'"&$Q11&"'!$F$9:$F$408"),$D11),"")) | I11: =IF(OR(OR($C11="",$Q11=""),N(E11)=0),"",H11/E11) | J11: =IF(OR($C11="",$Q11=""),"",N(E11)-N(H11)) | K11: =IF(OR($C11="",$Q11=""),"",IFERROR(SUMIFS(INDIRECT("'"&$Q11&"'!$K$9:$K$408"),INDIRECT("'"&$Q11&"'!$D$9:$D$408"),$P11,INDIRECT("'"&$Q11&"'!$E$9:$E$408"),$C11,INDIRECT("'"&$Q11&"'!$F$9:$F$408"),$D11),"")) | L11: =IF(OR($C11="",$Q11=""),"",IFERROR(SUMIFS(INDIRECT("'"&$Q11&"'!$Q$9:$Q$408"),INDIRECT("'"&$Q11&"'!$D$9:$D$408"),$P11,INDIRECT("'"&$Q11&"'!$E$9:$E$408"),$C11,INDIRECT("'"&$Q11&"'!$F$9:$F$408"),$D11),"")) | M11: =IF(OR($C11="",$Q11=""),"",IFERROR(SUMIFS(INDIRECT("'"&$Q11&"'!$M$9:$M$408"),INDIRECT("'"&$Q11&"'!$D$9:$D$408"),$P11,INDIRECT("'"&$Q11&"'!$E$9:$E$408"),$C11,INDIRECT("'"&$Q11&"'!$F$9:$F$408"),$D11),"")) | N11: =IF(OR($C11="",$Q11=""),"",IFERROR(SUMIFS(INDIRECT("'"&$Q11&"'!$V$9:$V$408"),INDIRECT("'"&$Q11&"'!$D$9:$D$408"),$P11,INDIRECT("'"&$Q11&"'!$E$9:$E$408"),$C11,INDIRECT("'"&$Q11&"'!$F$9:$F$408"),$D11),""))
B12: =IF(OR($C12="",$Q12=""),"",COUNTA($C$8:$C12)) | E12: =IF(OR($C12="",$Q12=""),"",IFERROR(SUMIFS(INDIRECT("'"&$Q12&"'!$G$9:$G$408"),INDIRECT("'"&$Q12&"'!$D$9:$D$408"),$P12,INDIRECT("'"&$Q12&"'!$E$9:$E$408"),$C12,INDIRECT("'"&$Q12&"'!$F$9:$F$408"),$D12),"")) | F12: =IF(OR($C12="",$Q12=""),"",IFERROR(SUMIFS(INDIRECT("'"&$Q12&"'!$H$9:$H$408"),INDIRECT("'"&$Q12&"'!$D$9:$D$408"),$P12,INDIRECT("'"&$Q12&"'!$E$9:$E$408"),$C12,INDIRECT("'"&$Q12&"'!$F$9:$F$408"),$D12),"")) | G12: =IF(OR($C12="",$Q12=""),"",IFERROR(SUMIFS(INDIRECT("'"&$Q12&"'!$I$9:$I$408"),INDIRECT("'"&$Q12&"'!$D$9:$D$408"),$P12,INDIRECT("'"&$Q12&"'!$E$9:$E$408"),$C12,INDIRECT("'"&$Q12&"'!$F$9:$F$408"),$D12),"")) | H12: =IF(OR($C12="",$Q12=""),"",IFERROR(SUMIFS(INDIRECT("'"&$Q12&"'!$R$9:$R$408"),INDIRECT("'"&$Q12&"'!$D$9:$D$408"),$P12,INDIRECT("'"&$Q12&"'!$E$9:$E$408"),$C12,INDIRECT("'"&$Q12&"'!$F$9:$F$408"),$D12),"")) | I12: =IF(OR(OR($C12="",$Q12=""),N(E12)=0),"",H12/E12) | J12: =IF(OR($C12="",$Q12=""),"",N(E12)-N(H12)) | K12: =IF(OR($C12="",$Q12=""),"",IFERROR(SUMIFS(INDIRECT("'"&$Q12&"'!$K$9:$K$408"),INDIRECT("'"&$Q12&"'!$D$9:$D$408"),$P12,INDIRECT("'"&$Q12&"'!$E$9:$E$408"),$C12,INDIRECT("'"&$Q12&"'!$F$9:$F$408"),$D12),"")) | L12: =IF(OR($C12="",$Q12=""),"",IFERROR(SUMIFS(INDIRECT("'"&$Q12&"'!$Q$9:$Q$408"),INDIRECT("'"&$Q12&"'!$D$9:$D$408"),$P12,INDIRECT("'"&$Q12&"'!$E$9:$E$408"),$C12,INDIRECT("'"&$Q12&"'!$F$9:$F$408"),$D12),"")) | M12: =IF(OR($C12="",$Q12=""),"",IFERROR(SUMIFS(INDIRECT("'"&$Q12&"'!$M$9:$M$408"),INDIRECT("'"&$Q12&"'!$D$9:$D$408"),$P12,INDIRECT("'"&$Q12&"'!$E$9:$E$408"),$C12,INDIRECT("'"&$Q12&"'!$F$9:$F$408"),$D12),"")) | N12: =IF(OR($C12="",$Q12=""),"",IFERROR(SUMIFS(INDIRECT("'"&$Q12&"'!$V$9:$V$408"),INDIRECT("'"&$Q12&"'!$D$9:$D$408"),$P12,INDIRECT("'"&$Q12&"'!$E$9:$E$408"),$C12,INDIRECT("'"&$Q12&"'!$F$9:$F$408"),$D12),""))
B13: =IF(OR($C13="",$Q13=""),"",COUNTA($C$8:$C13)) | E13: =IF(OR($C13="",$Q13=""),"",IFERROR(SUMIFS(INDIRECT("'"&$Q13&"'!$G$9:$G$408"),INDIRECT("'"&$Q13&"'!$D$9:$D$408"),$P13,INDIRECT("'"&$Q13&"'!$E$9:$E$408"),$C13,INDIRECT("'"&$Q13&"'!$F$9:$F$408"),$D13),"")) | F13: =IF(OR($C13="",$Q13=""),"",IFERROR(SUMIFS(INDIRECT("'"&$Q13&"'!$H$9:$H$408"),INDIRECT("'"&$Q13&"'!$D$9:$D$408"),$P13,INDIRECT("'"&$Q13&"'!$E$9:$E$408"),$C13,INDIRECT("'"&$Q13&"'!$F$9:$F$408"),$D13),"")) | G13: =IF(OR($C13="",$Q13=""),"",IFERROR(SUMIFS(INDIRECT("'"&$Q13&"'!$I$9:$I$408"),INDIRECT("'"&$Q13&"'!$D$9:$D$408"),$P13,INDIRECT("'"&$Q13&"'!$E$9:$E$408"),$C13,INDIRECT("'"&$Q13&"'!$F$9:$F$408"),$D13),"")) | H13: =IF(OR($C13="",$Q13=""),"",IFERROR(SUMIFS(INDIRECT("'"&$Q13&"'!$R$9:$R$408"),INDIRECT("'"&$Q13&"'!$D$9:$D$408"),$P13,INDIRECT("'"&$Q13&"'!$E$9:$E$408"),$C13,INDIRECT("'"&$Q13&"'!$F$9:$F$408"),$D13),"")) | I13: =IF(OR(OR($C13="",$Q13=""),N(E13)=0),"",H13/E13) | J13: =IF(OR($C13="",$Q13=""),"",N(E13)-N(H13)) | K13: =IF(OR($C13="",$Q13=""),"",IFERROR(SUMIFS(INDIRECT("'"&$Q13&"'!$K$9:$K$408"),INDIRECT("'"&$Q13&"'!$D$9:$D$408"),$P13,INDIRECT("'"&$Q13&"'!$E$9:$E$408"),$C13,INDIRECT("'"&$Q13&"'!$F$9:$F$408"),$D13),"")) | L13: =IF(OR($C13="",$Q13=""),"",IFERROR(SUMIFS(INDIRECT("'"&$Q13&"'!$Q$9:$Q$408"),INDIRECT("'"&$Q13&"'!$D$9:$D$408"),$P13,INDIRECT("'"&$Q13&"'!$E$9:$E$408"),$C13,INDIRECT("'"&$Q13&"'!$F$9:$F$408"),$D13),"")) | M13: =IF(OR($C13="",$Q13=""),"",IFERROR(SUMIFS(INDIRECT("'"&$Q13&"'!$M$9:$M$408"),INDIRECT("'"&$Q13&"'!$D$9:$D$408"),$P13,INDIRECT("'"&$Q13&"'!$E$9:$E$408"),$C13,INDIRECT("'"&$Q13&"'!$F$9:$F$408"),$D13),"")) | N13: =IF(OR($C13="",$Q13=""),"",IFERROR(SUMIFS(INDIRECT("'"&$Q13&"'!$V$9:$V$408"),INDIRECT("'"&$Q13&"'!$D$9:$D$408"),$P13,INDIRECT("'"&$Q13&"'!$E$9:$E$408"),$C13,INDIRECT("'"&$Q13&"'!$F$9:$F$408"),$D13),""))
B14: =IF(OR($C14="",$Q14=""),"",COUNTA($C$8:$C14)) | E14: =IF(OR($C14="",$Q14=""),"",IFERROR(SUMIFS(INDIRECT("'"&$Q14&"'!$G$9:$G$408"),INDIRECT("'"&$Q14&"'!$D$9:$D$408"),$P14,INDIRECT("'"&$Q14&"'!$E$9:$E$408"),$C14,INDIRECT("'"&$Q14&"'!$F$9:$F$408"),$D14),"")) | F14: =IF(OR($C14="",$Q14=""),"",IFERROR(SUMIFS(INDIRECT("'"&$Q14&"'!$H$9:$H$408"),INDIRECT("'"&$Q14&"'!$D$9:$D$408"),$P14,INDIRECT("'"&$Q14&"'!$E$9:$E$408"),$C14,INDIRECT("'"&$Q14&"'!$F$9:$F$408"),$D14),"")) | G14: =IF(OR($C14="",$Q14=""),"",IFERROR(SUMIFS(INDIRECT("'"&$Q14&"'!$I$9:$I$408"),INDIRECT("'"&$Q14&"'!$D$9:$D$408"),$P14,INDIRECT("'"&$Q14&"'!$E$9:$E$408"),$C14,INDIRECT("'"&$Q14&"'!$F$9:$F$408"),$D14),"")) | H14: =IF(OR($C14="",$Q14=""),"",IFERROR(SUMIFS(INDIRECT("'"&$Q14&"'!$R$9:$R$408"),INDIRECT("'"&$Q14&"'!$D$9:$D$408"),$P14,INDIRECT("'"&$Q14&"'!$E$9:$E$408"),$C14,INDIRECT("'"&$Q14&"'!$F$9:$F$408"),$D14),"")) | I14: =IF(OR(OR($C14="",$Q14=""),N(E14)=0),"",H14/E14) | J14: =IF(OR($C14="",$Q14=""),"",N(E14)-N(H14)) | K14: =IF(OR($C14="",$Q14=""),"",IFERROR(SUMIFS(INDIRECT("'"&$Q14&"'!$K$9:$K$408"),INDIRECT("'"&$Q14&"'!$D$9:$D$408"),$P14,INDIRECT("'"&$Q14&"'!$E$9:$E$408"),$C14,INDIRECT("'"&$Q14&"'!$F$9:$F$408"),$D14),"")) | L14: =IF(OR($C14="",$Q14=""),"",IFERROR(SUMIFS(INDIRECT("'"&$Q14&"'!$Q$9:$Q$408"),INDIRECT("'"&$Q14&"'!$D$9:$D$408"),$P14,INDIRECT("'"&$Q14&"'!$E$9:$E$408"),$C14,INDIRECT("'"&$Q14&"'!$F$9:$F$408"),$D14),"")) | M14: =IF(OR($C14="",$Q14=""),"",IFERROR(SUMIFS(INDIRECT("'"&$Q14&"'!$M$9:$M$408"),INDIRECT("'"&$Q14&"'!$D$9:$D$408"),$P14,INDIRECT("'"&$Q14&"'!$E$9:$E$408"),$C14,INDIRECT("'"&$Q14&"'!$F$9:$F$408"),$D14),"")) | N14: =IF(OR($C14="",$Q14=""),"",IFERROR(SUMIFS(INDIRECT("'"&$Q14&"'!$V$9:$V$408"),INDIRECT("'"&$Q14&"'!$D$9:$D$408"),$P14,INDIRECT("'"&$Q14&"'!$E$9:$E$408"),$C14,INDIRECT("'"&$Q14&"'!$F$9:$F$408"),$D14),""))
B15: =IF(OR($C15="",$Q15=""),"",COUNTA($C$8:$C15)) | E15: =IF(OR($C15="",$Q15=""),"",IFERROR(SUMIFS(INDIRECT("'"&$Q15&"'!$G$9:$G$408"),INDIRECT("'"&$Q15&"'!$D$9:$D$408"),$P15,INDIRECT("'"&$Q15&"'!$E$9:$E$408"),$C15,INDIRECT("'"&$Q15&"'!$F$9:$F$408"),$D15),"")) | F15: =IF(OR($C15="",$Q15=""),"",IFERROR(SUMIFS(INDIRECT("'"&$Q15&"'!$H$9:$H$408"),INDIRECT("'"&$Q15&"'!$D$9:$D$408"),$P15,INDIRECT("'"&$Q15&"'!$E$9:$E$408"),$C15,INDIRECT("'"&$Q15&"'!$F$9:$F$408"),$D15),"")) | G15: =IF(OR($C15="",$Q15=""),"",IFERROR(SUMIFS(INDIRECT("'"&$Q15&"'!$I$9:$I$408"),INDIRECT("'"&$Q15&"'!$D$9:$D$408"),$P15,INDIRECT("'"&$Q15&"'!$E$9:$E$408"),$C15,INDIRECT("'"&$Q15&"'!$F$9:$F$408"),$D15),"")) | H15: =IF(OR($C15="",$Q15=""),"",IFERROR(SUMIFS(INDIRECT("'"&$Q15&"'!$R$9:$R$408"),INDIRECT("'"&$Q15&"'!$D$9:$D$408"),$P15,INDIRECT("'"&$Q15&"'!$E$9:$E$408"),$C15,INDIRECT("'"&$Q15&"'!$F$9:$F$408"),$D15),"")) | I15: =IF(OR(OR($C15="",$Q15=""),N(E15)=0),"",H15/E15) | J15: =IF(OR($C15="",$Q15=""),"",N(E15)-N(H15)) | K15: =IF(OR($C15="",$Q15=""),"",IFERROR(SUMIFS(INDIRECT("'"&$Q15&"'!$K$9:$K$408"),INDIRECT("'"&$Q15&"'!$D$9:$D$408"),$P15,INDIRECT("'"&$Q15&"'!$E$9:$E$408"),$C15,INDIRECT("'"&$Q15&"'!$F$9:$F$408"),$D15),"")) | L15: =IF(OR($C15="",$Q15=""),"",IFERROR(SUMIFS(INDIRECT("'"&$Q15&"'!$Q$9:$Q$408"),INDIRECT("'"&$Q15&"'!$D$9:$D$408"),$P15,INDIRECT("'"&$Q15&"'!$E$9:$E$408"),$C15,INDIRECT("'"&$Q15&"'!$F$9:$F$408"),$D15),"")) | M15: =IF(OR($C15="",$Q15=""),"",IFERROR(SUMIFS(INDIRECT("'"&$Q15&"'!$M$9:$M$408"),INDIRECT("'"&$Q15&"'!$D$9:$D$408"),$P15,INDIRECT("'"&$Q15&"'!$E$9:$E$408"),$C15,INDIRECT("'"&$Q15&"'!$F$9:$F$408"),$D15),"")) | N15: =IF(OR($C15="",$Q15=""),"",IFERROR(SUMIFS(INDIRECT("'"&$Q15&"'!$V$9:$V$408"),INDIRECT("'"&$Q15&"'!$D$9:$D$408"),$P15,INDIRECT("'"&$Q15&"'!$E$9:$E$408"),$C15,INDIRECT("'"&$Q15&"'!$F$9:$F$408"),$D15),""))
B16: =IF(OR($C16="",$Q16=""),"",COUNTA($C$8:$C16)) | E16: =IF(OR($C16="",$Q16=""),"",IFERROR(SUMIFS(INDIRECT("'"&$Q16&"'!$G$9:$G$408"),INDIRECT("'"&$Q16&"'!$D$9:$D$408"),$P16,INDIRECT("'"&$Q16&"'!$E$9:$E$408"),$C16,INDIRECT("'"&$Q16&"'!$F$9:$F$408"),$D16),"")) | F16: =IF(OR($C16="",$Q16=""),"",IFERROR(SUMIFS(INDIRECT("'"&$Q16&"'!$H$9:$H$408"),INDIRECT("'"&$Q16&"'!$D$9:$D$408"),$P16,INDIRECT("'"&$Q16&"'!$E$9:$E$408"),$C16,INDIRECT("'"&$Q16&"'!$F$9:$F$408"),$D16),"")) | G16: =IF(OR($C16="",$Q16=""),"",IFERROR(SUMIFS(INDIRECT("'"&$Q16&"'!$I$9:$I$408"),INDIRECT("'"&$Q16&"'!$D$9:$D$408"),$P16,INDIRECT("'"&$Q16&"'!$E$9:$E$408"),$C16,INDIRECT("'"&$Q16&"'!$F$9:$F$408"),$D16),"")) | H16: =IF(OR($C16="",$Q16=""),"",IFERROR(SUMIFS(INDIRECT("'"&$Q16&"'!$R$9:$R$408"),INDIRECT("'"&$Q16&"'!$D$9:$D$408"),$P16,INDIRECT("'"&$Q16&"'!$E$9:$E$408"),$C16,INDIRECT("'"&$Q16&"'!$F$9:$F$408"),$D16),"")) | I16: =IF(OR(OR($C16="",$Q16=""),N(E16)=0),"",H16/E16) | J16: =IF(OR($C16="",$Q16=""),"",N(E16)-N(H16)) | K16: =IF(OR($C16="",$Q16=""),"",IFERROR(SUMIFS(INDIRECT("'"&$Q16&"'!$K$9:$K$408"),INDIRECT("'"&$Q16&"'!$D$9:$D$408"),$P16,INDIRECT("'"&$Q16&"'!$E$9:$E$408"),$C16,INDIRECT("'"&$Q16&"'!$F$9:$F$408"),$D16),"")) | L16: =IF(OR($C16="",$Q16=""),"",IFERROR(SUMIFS(INDIRECT("'"&$Q16&"'!$Q$9:$Q$408"),INDIRECT("'"&$Q16&"'!$D$9:$D$408"),$P16,INDIRECT("'"&$Q16&"'!$E$9:$E$408"),$C16,INDIRECT("'"&$Q16&"'!$F$9:$F$408"),$D16),"")) | M16: =IF(OR($C16="",$Q16=""),"",IFERROR(SUMIFS(INDIRECT("'"&$Q16&"'!$M$9:$M$408"),INDIRECT("'"&$Q16&"'!$D$9:$D$408"),$P16,INDIRECT("'"&$Q16&"'!$E$9:$E$408"),$C16,INDIRECT("'"&$Q16&"'!$F$9:$F$408"),$D16),"")) | N16: =IF(OR($C16="",$Q16=""),"",IFERROR(SUMIFS(INDIRECT("'"&$Q16&"'!$V$9:$V$408"),INDIRECT("'"&$Q16&"'!$D$9:$D$408"),$P16,INDIRECT("'"&$Q16&"'!$E$9:$E$408"),$C16,INDIRECT("'"&$Q16&"'!$F$9:$F$408"),$D16),""))
B17: =IF(OR($C17="",$Q17=""),"",COUNTA($C$8:$C17)) | E17: =IF(OR($C17="",$Q17=""),"",IFERROR(SUMIFS(INDIRECT("'"&$Q17&"'!$G$9:$G$408"),INDIRECT("'"&$Q17&"'!$D$9:$D$408"),$P17,INDIRECT("'"&$Q17&"'!$E$9:$E$408"),$C17,INDIRECT("'"&$Q17&"'!$F$9:$F$408"),$D17),"")) | F17: =IF(OR($C17="",$Q17=""),"",IFERROR(SUMIFS(INDIRECT("'"&$Q17&"'!$H$9:$H$408"),INDIRECT("'"&$Q17&"'!$D$9:$D$408"),$P17,INDIRECT("'"&$Q17&"'!$E$9:$E$408"),$C17,INDIRECT("'"&$Q17&"'!$F$9:$F$408"),$D17),"")) | G17: =IF(OR($C17="",$Q17=""),"",IFERROR(SUMIFS(INDIRECT("'"&$Q17&"'!$I$9:$I$408"),INDIRECT("'"&$Q17&"'!$D$9:$D$408"),$P17,INDIRECT("'"&$Q17&"'!$E$9:$E$408"),$C17,INDIRECT("'"&$Q17&"'!$F$9:$F$408"),$D17),"")) | H17: =IF(OR($C17="",$Q17=""),"",IFERROR(SUMIFS(INDIRECT("'"&$Q17&"'!$R$9:$R$408"),INDIRECT("'"&$Q17&"'!$D$9:$D$408"),$P17,INDIRECT("'"&$Q17&"'!$E$9:$E$408"),$C17,INDIRECT("'"&$Q17&"'!$F$9:$F$408"),$D17),"")) | I17: =IF(OR(OR($C17="",$Q17=""),N(E17)=0),"",H17/E17) | J17: =IF(OR($C17="",$Q17=""),"",N(E17)-N(H17)) | K17: =IF(OR($C17="",$Q17=""),"",IFERROR(SUMIFS(INDIRECT("'"&$Q17&"'!$K$9:$K$408"),INDIRECT("'"&$Q17&"'!$D$9:$D$408"),$P17,INDIRECT("'"&$Q17&"'!$E$9:$E$408"),$C17,INDIRECT("'"&$Q17&"'!$F$9:$F$408"),$D17),"")) | L17: =IF(OR($C17="",$Q17=""),"",IFERROR(SUMIFS(INDIRECT("'"&$Q17&"'!$Q$9:$Q$408"),INDIRECT("'"&$Q17&"'!$D$9:$D$408"),$P17,INDIRECT("'"&$Q17&"'!$E$9:$E$408"),$C17,INDIRECT("'"&$Q17&"'!$F$9:$F$408"),$D17),"")) | M17: =IF(OR($C17="",$Q17=""),"",IFERROR(SUMIFS(INDIRECT("'"&$Q17&"'!$M$9:$M$408"),INDIRECT("'"&$Q17&"'!$D$9:$D$408"),$P17,INDIRECT("'"&$Q17&"'!$E$9:$E$408"),$C17,INDIRECT("'"&$Q17&"'!$F$9:$F$408"),$D17),"")) | N17: =IF(OR($C17="",$Q17=""),"",IFERROR(SUMIFS(INDIRECT("'"&$Q17&"'!$V$9:$V$408"),INDIRECT("'"&$Q17&"'!$D$9:$D$408"),$P17,INDIRECT("'"&$Q17&"'!$E$9:$E$408"),$C17,INDIRECT("'"&$Q17&"'!$F$9:$F$408"),$D17),""))
B18: =IF(OR($C18="",$Q18=""),"",COUNTA($C$8:$C18)) | E18: =IF(OR($C18="",$Q18=""),"",IFERROR(SUMIFS(INDIRECT("'"&$Q18&"'!$G$9:$G$408"),INDIRECT("'"&$Q18&"'!$D$9:$D$408"),$P18,INDIRECT("'"&$Q18&"'!$E$9:$E$408"),$C18,INDIRECT("'"&$Q18&"'!$F$9:$F$408"),$D18),"")) | F18: =IF(OR($C18="",$Q18=""),"",IFERROR(SUMIFS(INDIRECT("'"&$Q18&"'!$H$9:$H$408"),INDIRECT("'"&$Q18&"'!$D$9:$D$408"),$P18,INDIRECT("'"&$Q18&"'!$E$9:$E$408"),$C18,INDIRECT("'"&$Q18&"'!$F$9:$F$408"),$D18),"")) | G18: =IF(OR($C18="",$Q18=""),"",IFERROR(SUMIFS(INDIRECT("'"&$Q18&"'!$I$9:$I$408"),INDIRECT("'"&$Q18&"'!$D$9:$D$408"),$P18,INDIRECT("'"&$Q18&"'!$E$9:$E$408"),$C18,INDIRECT("'"&$Q18&"'!$F$9:$F$408"),$D18),"")) | H18: =IF(OR($C18="",$Q18=""),"",IFERROR(SUMIFS(INDIRECT("'"&$Q18&"'!$R$9:$R$408"),INDIRECT("'"&$Q18&"'!$D$9:$D$408"),$P18,INDIRECT("'"&$Q18&"'!$E$9:$E$408"),$C18,INDIRECT("'"&$Q18&"'!$F$9:$F$408"),$D18),"")) | I18: =IF(OR(OR($C18="",$Q18=""),N(E18)=0),"",H18/E18) | J18: =IF(OR($C18="",$Q18=""),"",N(E18)-N(H18)) | K18: =IF(OR($C18="",$Q18=""),"",IFERROR(SUMIFS(INDIRECT("'"&$Q18&"'!$K$9:$K$408"),INDIRECT("'"&$Q18&"'!$D$9:$D$408"),$P18,INDIRECT("'"&$Q18&"'!$E$9:$E$408"),$C18,INDIRECT("'"&$Q18&"'!$F$9:$F$408"),$D18),"")) | L18: =IF(OR($C18="",$Q18=""),"",IFERROR(SUMIFS(INDIRECT("'"&$Q18&"'!$Q$9:$Q$408"),INDIRECT("'"&$Q18&"'!$D$9:$D$408"),$P18,INDIRECT("'"&$Q18&"'!$E$9:$E$408"),$C18,INDIRECT("'"&$Q18&"'!$F$9:$F$408"),$D18),"")) | M18: =IF(OR($C18="",$Q18=""),"",IFERROR(SUMIFS(INDIRECT("'"&$Q18&"'!$M$9:$M$408"),INDIRECT("'"&$Q18&"'!$D$9:$D$408"),$P18,INDIRECT("'"&$Q18&"'!$E$9:$E$408"),$C18,INDIRECT("'"&$Q18&"'!$F$9:$F$408"),$D18),"")) | N18: =IF(OR($C18="",$Q18=""),"",IFERROR(SUMIFS(INDIRECT("'"&$Q18&"'!$V$9:$V$408"),INDIRECT("'"&$Q18&"'!$D$9:$D$408"),$P18,INDIRECT("'"&$Q18&"'!$E$9:$E$408"),$C18,INDIRECT("'"&$Q18&"'!$F$9:$F$408"),$D18),""))
B19: =IF(OR($C19="",$Q19=""),"",COUNTA($C$8:$C19)) | E19: =IF(OR($C19="",$Q19=""),"",IFERROR(SUMIFS(INDIRECT("'"&$Q19&"'!$G$9:$G$408"),INDIRECT("'"&$Q19&"'!$D$9:$D$408"),$P19,INDIRECT("'"&$Q19&"'!$E$9:$E$408"),$C19,INDIRECT("'"&$Q19&"'!$F$9:$F$408"),$D19),"")) | F19: =IF(OR($C19="",$Q19=""),"",IFERROR(SUMIFS(INDIRECT("'"&$Q19&"'!$H$9:$H$408"),INDIRECT("'"&$Q19&"'!$D$9:$D$408"),$P19,INDIRECT("'"&$Q19&"'!$E$9:$E$408"),$C19,INDIRECT("'"&$Q19&"'!$F$9:$F$408"),$D19),"")) | G19: =IF(OR($C19="",$Q19=""),"",IFERROR(SUMIFS(INDIRECT("'"&$Q19&"'!$I$9:$I$408"),INDIRECT("'"&$Q19&"'!$D$9:$D$408"),$P19,INDIRECT("'"&$Q19&"'!$E$9:$E$408"),$C19,INDIRECT("'"&$Q19&"'!$F$9:$F$408"),$D19),"")) | H19: =IF(OR($C19="",$Q19=""),"",IFERROR(SUMIFS(INDIRECT("'"&$Q19&"'!$R$9:$R$408"),INDIRECT("'"&$Q19&"'!$D$9:$D$408"),$P19,INDIRECT("'"&$Q19&"'!$E$9:$E$408"),$C19,INDIRECT("'"&$Q19&"'!$F$9:$F$408"),$D19),"")) | I19: =IF(OR(OR($C19="",$Q19=""),N(E19)=0),"",H19/E19) | J19: =IF(OR($C19="",$Q19=""),"",N(E19)-N(H19)) | K19: =IF(OR($C19="",$Q19=""),"",IFERROR(SUMIFS(INDIRECT("'"&$Q19&"'!$K$9:$K$408"),INDIRECT("'"&$Q19&"'!$D$9:$D$408"),$P19,INDIRECT("'"&$Q19&"'!$E$9:$E$408"),$C19,INDIRECT("'"&$Q19&"'!$F$9:$F$408"),$D19),"")) | L19: =IF(OR($C19="",$Q19=""),"",IFERROR(SUMIFS(INDIRECT("'"&$Q19&"'!$Q$9:$Q$408"),INDIRECT("'"&$Q19&"'!$D$9:$D$408"),$P19,INDIRECT("'"&$Q19&"'!$E$9:$E$408"),$C19,INDIRECT("'"&$Q19&"'!$F$9:$F$408"),$D19),"")) | M19: =IF(OR($C19="",$Q19=""),"",IFERROR(SUMIFS(INDIRECT("'"&$Q19&"'!$M$9:$M$408"),INDIRECT("'"&$Q19&"'!$D$9:$D$408"),$P19,INDIRECT("'"&$Q19&"'!$E$9:$E$408"),$C19,INDIRECT("'"&$Q19&"'!$F$9:$F$408"),$D19),"")) | N19: =IF(OR($C19="",$Q19=""),"",IFERROR(SUMIFS(INDIRECT("'"&$Q19&"'!$V$9:$V$408"),INDIRECT("'"&$Q19&"'!$D$9:$D$408"),$P19,INDIRECT("'"&$Q19&"'!$E$9:$E$408"),$C19,INDIRECT("'"&$Q19&"'!$F$9:$F$408"),$D19),""))
... B157: =IF(OR($C157="",$Q157=""),"",COUNTA($C$8:$C157)) | E157: =IF(OR($C157="",$Q157=""),"",IFERROR(SUMIFS(INDIRECT("'"&$Q157&"'!$G$9:$G$408"),INDIRECT("'"&$Q157&"'!$D$9:$D$408"),$P157,INDIRECT("'"&$Q157&"'!$E$9:$E$408"),$C157,INDIRECT("'"&$Q157&"'!$F$9:$F$408"),$D157),"")) | F157: =IF(OR($C157="",$Q157=""),"",IFERROR(SUMIFS(INDIRECT("'"&$Q157&"'!$H$9:$H$408"),INDIRECT("'"&$Q157&"'!$D$9:$D$408"),$P157,INDIRECT("'"&$Q157&"'!$E$9:$E$408"),$C157,INDIRECT("'"&$Q157&"'!$F$9:$F$408"),$D157),"")) | G157: =IF(OR($C157="",$Q157=""),"",IFERROR(SUMIFS(INDIRECT("'"&$Q157&"'!$I$9:$I$408"),INDIRECT("'"&$Q157&"'!$D$9:$D$408"),$P157,INDIRECT("'"&$Q157&"'!$E$9:$E$408"),$C157,INDIRECT("'"&$Q157&"'!$F$9:$F$408"),$D157),"")) | H157: =IF(OR($C157="",$Q157=""),"",IFERROR(SUMIFS(INDIRECT("'"&$Q157&"'!$R$9:$R$408"),INDIRECT("'"&$Q157&"'!$D$9:$D$408"),$P157,INDIRECT("'"&$Q157&"'!$E$9:$E$408"),$C157,INDIRECT("'"&$Q157&"'!$F$9:$F$408"),$D157),"")) | I157: =IF(OR(OR($C157="",$Q157=""),N(E157)=0),"",H157/E157) | J157: =IF(OR($C157="",$Q157=""),"",N(E157)-N(H157)) | K157: =IF(OR($C157="",$Q157=""),"",IFERROR(SUMIFS(INDIRECT("'"&$Q157&"'!$K$9:$K$408"),INDIRECT("'"&$Q157&"'!$D$9:$D$408"),$P157,INDIRECT("'"&$Q157&"'!$E$9:$E$408"),$C157,INDIRECT("'"&$Q157&"'!$F$9:$F$408"),$D157),"")) | L157: =IF(OR($C157="",$Q157=""),"",IFERROR(SUMIFS(INDIRECT("'"&$Q157&"'!$Q$9:$Q$408"),INDIRECT("'"&$Q157&"'!$D$9:$D$408"),$P157,INDIRECT("'"&$Q157&"'!$E$9:$E$408"),$C157,INDIRECT("'"&$Q157&"'!$F$9:$F$408"),$D157),"")) | M157: =IF(OR($C157="",$Q157=""),"",IFERROR(SUMIFS(INDIRECT("'"&$Q157&"'!$M$9:$M$408"),INDIRECT("'"&$Q157&"'!$D$9:$D$408"),$P157,INDIRECT("'"&$Q157&"'!$E$9:$E$408"),$C157,INDIRECT("'"&$Q157&"'!$F$9:$F$408"),$D157),"")) | N157: =IF(OR($C157="",$Q157=""),"",IFERROR(SUMIFS(INDIRECT("'"&$Q157&"'!$V$9:$V$408"),INDIRECT("'"&$Q157&"'!$D$9:$D$408"),$P157,INDIRECT("'"&$Q157&"'!$E$9:$E$408"),$C157,INDIRECT("'"&$Q157&"'!$F$9:$F$408"),$D157),""))

Sheet Piling
B2: JSW
C3: Piling Works — Backup Sheet (UOM: Nos)
C4: =Config!$C$4
S5: Data date: | T5: =Config!$C$6
S6: Reporting date: | T6: =Config!$C$7
B7: SL. | C7: Name of the Structures | D7: Area | E7: Activity | F7: Agency / Contractor | G7: Scope | H7: Drawing Released | I7: Cum Front Available | J7: Achieved till last month | K7: Plan FTM | L7: Plan FTD | M7: Achieved FTD | N7: Achieved FTM till previous date | O7: Variance for the Day | P7: Reason(s) for Variance | Q7: Achieved FTM till date | R7: Workdone Till Date | S7: % Complete | T7: Balance | U7: Remarks | V7: Available Manpower
B8: a | C8: b | D8: c | E8: d | F8: e | G8: f | H8: g | I8: h | J8: i | K8: j | L8: k | M8: l | N8: m | O8: n = k-l | P8: o | Q8: p = l+m | R8: q = i+p | S8: r = (q/f)x100 | T8: s = f-q | U8: t | V8: u
B9: =IF($C9="","",COUNTA($C$9:$C9)) | O9: =IF($C9="","",N(L9)-N(M9)) | Q9: =IF($C9="","",N(M9)+N(N9)) | R9: =IF($C9="","",N(J9)+N(Q9)) | S9: =IF(OR($C9="",N($G9)=0),"",R9/$G9) | T9: =IF($C9="","",N($G9)-N(R9))
B10: =IF($C10="","",COUNTA($C$9:$C10)) | O10: =IF($C10="","",N(L10)-N(M10)) | Q10: =IF($C10="","",N(M10)+N(N10)) | R10: =IF($C10="","",N(J10)+N(Q10)) | S10: =IF(OR($C10="",N($G10)=0),"",R10/$G10) | T10: =IF($C10="","",N($G10)-N(R10))
B11: =IF($C11="","",COUNTA($C$9:$C11)) | O11: =IF($C11="","",N(L11)-N(M11)) | Q11: =IF($C11="","",N(M11)+N(N11)) | R11: =IF($C11="","",N(J11)+N(Q11)) | S11: =IF(OR($C11="",N($G11)=0),"",R11/$G11) | T11: =IF($C11="","",N($G11)-N(R11))
B12: =IF($C12="","",COUNTA($C$9:$C12)) | O12: =IF($C12="","",N(L12)-N(M12)) | Q12: =IF($C12="","",N(M12)+N(N12)) | R12: =IF($C12="","",N(J12)+N(Q12)) | S12: =IF(OR($C12="",N($G12)=0),"",R12/$G12) | T12: =IF($C12="","",N($G12)-N(R12))
B13: =IF($C13="","",COUNTA($C$9:$C13)) | O13: =IF($C13="","",N(L13)-N(M13)) | Q13: =IF($C13="","",N(M13)+N(N13)) | R13: =IF($C13="","",N(J13)+N(Q13)) | S13: =IF(OR($C13="",N($G13)=0),"",R13/$G13) | T13: =IF($C13="","",N($G13)-N(R13))
B14: =IF($C14="","",COUNTA($C$9:$C14)) | O14: =IF($C14="","",N(L14)-N(M14)) | Q14: =IF($C14="","",N(M14)+N(N14)) | R14: =IF($C14="","",N(J14)+N(Q14)) | S14: =IF(OR($C14="",N($G14)=0),"",R14/$G14) | T14: =IF($C14="","",N($G14)-N(R14))
B15: =IF($C15="","",COUNTA($C$9:$C15)) | O15: =IF($C15="","",N(L15)-N(M15)) | Q15: =IF($C15="","",N(M15)+N(N15)) | R15: =IF($C15="","",N(J15)+N(Q15)) | S15: =IF(OR($C15="",N($G15)=0),"",R15/$G15) | T15: =IF($C15="","",N($G15)-N(R15))
B16: =IF($C16="","",COUNTA($C$9:$C16)) | O16: =IF($C16="","",N(L16)-N(M16)) | Q16: =IF($C16="","",N(M16)+N(N16)) | R16: =IF($C16="","",N(J16)+N(Q16)) | S16: =IF(OR($C16="",N($G16)=0),"",R16/$G16) | T16: =IF($C16="","",N($G16)-N(R16))
B17: =IF($C17="","",COUNTA($C$9:$C17)) | O17: =IF($C17="","",N(L17)-N(M17)) | Q17: =IF($C17="","",N(M17)+N(N17)) | R17: =IF($C17="","",N(J17)+N(Q17)) | S17: =IF(OR($C17="",N($G17)=0),"",R17/$G17) | T17: =IF($C17="","",N($G17)-N(R17))
B18: =IF($C18="","",COUNTA($C$9:$C18)) | O18: =IF($C18="","",N(L18)-N(M18)) | Q18: =IF($C18="","",N(M18)+N(N18)) | R18: =IF($C18="","",N(J18)+N(Q18)) | S18: =IF(OR($C18="",N($G18)=0),"",R18/$G18) | T18: =IF($C18="","",N($G18)-N(R18))
B19: =IF($C19="","",COUNTA($C$9:$C19)) | O19: =IF($C19="","",N(L19)-N(M19)) | Q19: =IF($C19="","",N(M19)+N(N19)) | R19: =IF($C19="","",N(J19)+N(Q19)) | S19: =IF(OR($C19="",N($G19)=0),"",R19/$G19) | T19: =IF($C19="","",N($G19)-N(R19))
B20: =IF($C20="","",COUNTA($C$9:$C20)) | O20: =IF($C20="","",N(L20)-N(M20)) | Q20: =IF($C20="","",N(M20)+N(N20)) | R20: =IF($C20="","",N(J20)+N(Q20)) | S20: =IF(OR($C20="",N($G20)=0),"",R20/$G20) | T20: =IF($C20="","",N($G20)-N(R20))
... B408: =IF($C408="","",COUNTA($C$9:$C408)) | O408: =IF($C408="","",N(L408)-N(M408)) | Q408: =IF($C408="","",N(M408)+N(N408)) | R408: =IF($C408="","",N(J408)+N(Q408)) | S408: =IF(OR($C408="",N($G408)=0),"",R408/$G408) | T408: =IF($C408="","",N($G408)-N(R408))

Sheet Civil
B2: JSW
C3: Civil Works — Backup Sheet (UOM: Cum)
C4: =Config!$C$4
S5: Data date: | T5: =Config!$C$6
S6: Reporting date: | T6: =Config!$C$7
B7: SL. | C7: Name of the Structures | D7: Area | E7: Activity | F7: Agency / Contractor | G7: Scope | H7: Drawing Released | I7: Cum Front Available | J7: Achieved till last month | K7: Plan FTM | L7: Plan FTD | M7: Achieved FTD | N7: Achieved FTM till previous date | O7: Variance for the Day | P7: Reason(s) for Variance | Q7: Achieved FTM till date | R7: Workdone Till Date | S7: % Complete | T7: Balance | U7: Remarks | V7: Available Manpower
B8: a | C8: b | D8: c | E8: d | F8: e | G8: f | H8: g | I8: h | J8: i | K8: j | L8: k | M8: l | N8: m | O8: n = k-l | P8: o | Q8: p = l+m | R8: q = i+p | S8: r = (q/f)x100 | T8: s = f-q | U8: t | V8: u
B9: =IF($C9="","",COUNTA($C$9:$C9)) | O9: =IF($C9="","",N(L9)-N(M9)) | Q9: =IF($C9="","",N(M9)+N(N9)) | R9: =IF($C9="","",N(J9)+N(Q9)) | S9: =IF(OR($C9="",N($G9)=0),"",R9/$G9) | T9: =IF($C9="","",N($G9)-N(R9))
B10: =IF($C10="","",COUNTA($C$9:$C10)) | O10: =IF($C10="","",N(L10)-N(M10)) | Q10: =IF($C10="","",N(M10)+N(N10)) | R10: =IF($C10="","",N(J10)+N(Q10)) | S10: =IF(OR($C10="",N($G10)=0),"",R10/$G10) | T10: =IF($C10="","",N($G10)-N(R10))
B11: =IF($C11="","",COUNTA($C$9:$C11)) | O11: =IF($C11="","",N(L11)-N(M11)) | Q11: =IF($C11="","",N(M11)+N(N11)) | R11: =IF($C11="","",N(J11)+N(Q11)) | S11: =IF(OR($C11="",N($G11)=0),"",R11/$G11) | T11: =IF($C11="","",N($G11)-N(R11))
B12: =IF($C12="","",COUNTA($C$9:$C12)) | O12: =IF($C12="","",N(L12)-N(M12)) | Q12: =IF($C12="","",N(M12)+N(N12)) | R12: =IF($C12="","",N(J12)+N(Q12)) | S12: =IF(OR($C12="",N($G12)=0),"",R12/$G12) | T12: =IF($C12="","",N($G12)-N(R12))
B13: =IF($C13="","",COUNTA($C$9:$C13)) | O13: =IF($C13="","",N(L13)-N(M13)) | Q13: =IF($C13="","",N(M13)+N(N13)) | R13: =IF($C13="","",N(J13)+N(Q13)) | S13: =IF(OR($C13="",N($G13)=0),"",R13/$G13) | T13: =IF($C13="","",N($G13)-N(R13))
B14: =IF($C14="","",COUNTA($C$9:$C14)) | O14: =IF($C14="","",N(L14)-N(M14)) | Q14: =IF($C14="","",N(M14)+N(N14)) | R14: =IF($C14="","",N(J14)+N(Q14)) | S14: =IF(OR($C14="",N($G14)=0),"",R14/$G14) | T14: =IF($C14="","",N($G14)-N(R14))
B15: =IF($C15="","",COUNTA($C$9:$C15)) | O15: =IF($C15="","",N(L15)-N(M15)) | Q15: =IF($C15="","",N(M15)+N(N15)) | R15: =IF($C15="","",N(J15)+N(Q15)) | S15: =IF(OR($C15="",N($G15)=0),"",R15/$G15) | T15: =IF($C15="","",N($G15)-N(R15))
B16: =IF($C16="","",COUNTA($C$9:$C16)) | O16: =IF($C16="","",N(L16)-N(M16)) | Q16: =IF($C16="","",N(M16)+N(N16)) | R16: =IF($C16="","",N(J16)+N(Q16)) | S16: =IF(OR($C16="",N($G16)=0),"",R16/$G16) | T16: =IF($C16="","",N($G16)-N(R16))
B17: =IF($C17="","",COUNTA($C$9:$C17)) | O17: =IF($C17="","",N(L17)-N(M17)) | Q17: =IF($C17="","",N(M17)+N(N17)) | R17: =IF($C17="","",N(J17)+N(Q17)) | S17: =IF(OR($C17="",N($G17)=0),"",R17/$G17) | T17: =IF($C17="","",N($G17)-N(R17))
B18: =IF($C18="","",COUNTA($C$9:$C18)) | O18: =IF($C18="","",N(L18)-N(M18)) | Q18: =IF($C18="","",N(M18)+N(N18)) | R18: =IF($C18="","",N(J18)+N(Q18)) | S18: =IF(OR($C18="",N($G18)=0),"",R18/$G18) | T18: =IF($C18="","",N($G18)-N(R18))
B19: =IF($C19="","",COUNTA($C$9:$C19)) | O19: =IF($C19="","",N(L19)-N(M19)) | Q19: =IF($C19="","",N(M19)+N(N19)) | R19: =IF($C19="","",N(J19)+N(Q19)) | S19: =IF(OR($C19="",N($G19)=0),"",R19/$G19) | T19: =IF($C19="","",N($G19)-N(R19))
B20: =IF($C20="","",COUNTA($C$9:$C20)) | O20: =IF($C20="","",N(L20)-N(M20)) | Q20: =IF($C20="","",N(M20)+N(N20)) | R20: =IF($C20="","",N(J20)+N(Q20)) | S20: =IF(OR($C20="",N($G20)=0),"",R20/$G20) | T20: =IF($C20="","",N($G20)-N(R20))
... B408: =IF($C408="","",COUNTA($C$9:$C408)) | O408: =IF($C408="","",N(L408)-N(M408)) | Q408: =IF($C408="","",N(M408)+N(N408)) | R408: =IF($C408="","",N(J408)+N(Q408)) | S408: =IF(OR($C408="",N($G408)=0),"",R408/$G408) | T408: =IF($C408="","",N($G408)-N(R408))

Sheet Structural
B2: JSW
C3: Structural Supply — Backup Sheet (UOM: MT)
C4: =Config!$C$4
S5: Data date: | T5: =Config!$C$6
S6: Reporting date: | T6: =Config!$C$7
B7: SL. | C7: Name of the Structures | D7: Area | E7: Activity | F7: Agency / Contractor | G7: Scope | H7: Drawing Released | I7: Cum Front Available | J7: Achieved till last month | K7: Plan FTM | L7: Plan FTD | M7: Achieved FTD | N7: Achieved FTM till previous date | O7: Variance for the Day | P7: Reason(s) for Variance | Q7: Achieved FTM till date | R7: Workdone Till Date | S7: % Complete | T7: Balance | U7: Remarks | V7: Available Manpower
B8: a | C8: b | D8: c | E8: d | F8: e | G8: f | H8: g | I8: h | J8: i | K8: j | L8: k | M8: l | N8: m | O8: n = k-l | P8: o | Q8: p = l+m | R8: q = i+p | S8: r = (q/f)x100 | T8: s = f-q | U8: t | V8: u
B9: =IF($C9="","",COUNTA($C$9:$C9)) | O9: =IF($C9="","",N(L9)-N(M9)) | Q9: =IF($C9="","",N(M9)+N(N9)) | R9: =IF($C9="","",N(J9)+N(Q9)) | S9: =IF(OR($C9="",N($G9)=0),"",R9/$G9) | T9: =IF($C9="","",N($G9)-N(R9))
B10: =IF($C10="","",COUNTA($C$9:$C10)) | O10: =IF($C10="","",N(L10)-N(M10)) | Q10: =IF($C10="","",N(M10)+N(N10)) | R10: =IF($C10="","",N(J10)+N(Q10)) | S10: =IF(OR($C10="",N($G10)=0),"",R10/$G10) | T10: =IF($C10="","",N($G10)-N(R10))
B11: =IF($C11="","",COUNTA($C$9:$C11)) | O11: =IF($C11="","",N(L11)-N(M11)) | Q11: =IF($C11="","",N(M11)+N(N11)) | R11: =IF($C11="","",N(J11)+N(Q11)) | S11: =IF(OR($C11="",N($G11)=0),"",R11/$G11) | T11: =IF($C11="","",N($G11)-N(R11))
B12: =IF($C12="","",COUNTA($C$9:$C12)) | O12: =IF($C12="","",N(L12)-N(M12)) | Q12: =IF($C12="","",N(M12)+N(N12)) | R12: =IF($C12="","",N(J12)+N(Q12)) | S12: =IF(OR($C12="",N($G12)=0),"",R12/$G12) | T12: =IF($C12="","",N($G12)-N(R12))
B13: =IF($C13="","",COUNTA($C$9:$C13)) | O13: =IF($C13="","",N(L13)-N(M13)) | Q13: =IF($C13="","",N(M13)+N(N13)) | R13: =IF($C13="","",N(J13)+N(Q13)) | S13: =IF(OR($C13="",N($G13)=0),"",R13/$G13) | T13: =IF($C13="","",N($G13)-N(R13))
B14: =IF($C14="","",COUNTA($C$9:$C14)) | O14: =IF($C14="","",N(L14)-N(M14)) | Q14: =IF($C14="","",N(M14)+N(N14)) | R14: =IF($C14="","",N(J14)+N(Q14)) | S14: =IF(OR($C14="",N($G14)=0),"",R14/$G14) | T14: =IF($C14="","",N($G14)-N(R14))
B15: =IF($C15="","",COUNTA($C$9:$C15)) | O15: =IF($C15="","",N(L15)-N(M15)) | Q15: =IF($C15="","",N(M15)+N(N15)) | R15: =IF($C15="","",N(J15)+N(Q15)) | S15: =IF(OR($C15="",N($G15)=0),"",R15/$G15) | T15: =IF($C15="","",N($G15)-N(R15))
B16: =IF($C16="","",COUNTA($C$9:$C16)) | O16: =IF($C16="","",N(L16)-N(M16)) | Q16: =IF($C16="","",N(M16)+N(N16)) | R16: =IF($C16="","",N(J16)+N(Q16)) | S16: =IF(OR($C16="",N($G16)=0),"",R16/$G16) | T16: =IF($C16="","",N($G16)-N(R16))
B17: =IF($C17="","",COUNTA($C$9:$C17)) | O17: =IF($C17="","",N(L17)-N(M17)) | Q17: =IF($C17="","",N(M17)+N(N17)) | R17: =IF($C17="","",N(J17)+N(Q17)) | S17: =IF(OR($C17="",N($G17)=0),"",R17/$G17) | T17: =IF($C17="","",N($G17)-N(R17))
B18: =IF($C18="","",COUNTA($C$9:$C18)) | O18: =IF($C18="","",N(L18)-N(M18)) | Q18: =IF($C18="","",N(M18)+N(N18)) | R18: =IF($C18="","",N(J18)+N(Q18)) | S18: =IF(OR($C18="",N($G18)=0),"",R18/$G18) | T18: =IF($C18="","",N($G18)-N(R18))
B19: =IF($C19="","",COUNTA($C$9:$C19)) | O19: =IF($C19="","",N(L19)-N(M19)) | Q19: =IF($C19="","",N(M19)+N(N19)) | R19: =IF($C19="","",N(J19)+N(Q19)) | S19: =IF(OR($C19="",N($G19)=0),"",R19/$G19) | T19: =IF($C19="","",N($G19)-N(R19))
B20: =IF($C20="","",COUNTA($C$9:$C20)) | O20: =IF($C20="","",N(L20)-N(M20)) | Q20: =IF($C20="","",N(M20)+N(N20)) | R20: =IF($C20="","",N(J20)+N(Q20)) | S20: =IF(OR($C20="",N($G20)=0),"",R20/$G20) | T20: =IF($C20="","",N($G20)-N(R20))
... B408: =IF($C408="","",COUNTA($C$9:$C408)) | O408: =IF($C408="","",N(L408)-N(M408)) | Q408: =IF($C408="","",N(M408)+N(N408)) | R408: =IF($C408="","",N(J408)+N(Q408)) | S408: =IF(OR($C408="",N($G408)=0),"",R408/$G408) | T408: =IF($C408="","",N($G408)-N(R408))

Sheet Equipment
B2: JSW
C3: Equipment Erection — Backup Sheet (UOM: MT)
C4: =Config!$C$4
S5: Data date: | T5: =Config!$C$6
S6: Reporting date: | T6: =Config!$C$7
B7: SL. | C7: Name of the Structures | D7: Area | E7: Activity | F7: Agency / Contractor | G7: Scope | H7: Drawing Released | I7: Cum Front Available | J7: Achieved till last month | K7: Plan FTM | L7: Plan FTD | M7: Achieved FTD | N7: Achieved FTM till previous date | O7: Variance for the Day | P7: Reason(s) for Variance | Q7: Achieved FTM till date | R7: Workdone Till Date | S7: % Complete | T7: Balance | U7: Remarks | V7: Available Manpower
B8: a | C8: b | D8: c | E8: d | F8: e | G8: f | H8: g | I8: h | J8: i | K8: j | L8: k | M8: l | N8: m | O8: n = k-l | P8: o | Q8: p = l+m | R8: q = i+p | S8: r = (q/f)x100 | T8: s = f-q | U8: t | V8: u
B9: =IF($C9="","",COUNTA($C$9:$C9)) | O9: =IF($C9="","",N(L9)-N(M9)) | Q9: =IF($C9="","",N(M9)+N(N9)) | R9: =IF($C9="","",N(J9)+N(Q9)) | S9: =IF(OR($C9="",N($G9)=0),"",R9/$G9) | T9: =IF($C9="","",N($G9)-N(R9))
B10: =IF($C10="","",COUNTA($C$9:$C10)) | O10: =IF($C10="","",N(L10)-N(M10)) | Q10: =IF($C10="","",N(M10)+N(N10)) | R10: =IF($C10="","",N(J10)+N(Q10)) | S10: =IF(OR($C10="",N($G10)=0),"",R10/$G10) | T10: =IF($C10="","",N($G10)-N(R10))
B11: =IF($C11="","",COUNTA($C$9:$C11)) | O11: =IF($C11="","",N(L11)-N(M11)) | Q11: =IF($C11="","",N(M11)+N(N11)) | R11: =IF($C11="","",N(J11)+N(Q11)) | S11: =IF(OR($C11="",N($G11)=0),"",R11/$G11) | T11: =IF($C11="","",N($G11)-N(R11))
B12: =IF($C12="","",COUNTA($C$9:$C12)) | O12: =IF($C12="","",N(L12)-N(M12)) | Q12: =IF($C12="","",N(M12)+N(N12)) | R12: =IF($C12="","",N(J12)+N(Q12)) | S12: =IF(OR($C12="",N($G12)=0),"",R12/$G12) | T12: =IF($C12="","",N($G12)-N(R12))
B13: =IF($C13="","",COUNTA($C$9:$C13)) | O13: =IF($C13="","",N(L13)-N(M13)) | Q13: =IF($C13="","",N(M13)+N(N13)) | R13: =IF($C13="","",N(J13)+N(Q13)) | S13: =IF(OR($C13="",N($G13)=0),"",R13/$G13) | T13: =IF($C13="","",N($G13)-N(R13))
B14: =IF($C14="","",COUNTA($C$9:$C14)) | O14: =IF($C14="","",N(L14)-N(M14)) | Q14: =IF($C14="","",N(M14)+N(N14)) | R14: =IF($C14="","",N(J14)+N(Q14)) | S14: =IF(OR($C14="",N($G14)=0),"",R14/$G14) | T14: =IF($C14="","",N($G14)-N(R14))
B15: =IF($C15="","",COUNTA($C$9:$C15)) | O15: =IF($C15="","",N(L15)-N(M15)) | Q15: =IF($C15="","",N(M15)+N(N15)) | R15: =IF($C15="","",N(J15)+N(Q15)) | S15: =IF(OR($C15="",N($G15)=0),"",R15/$G15) | T15: =IF($C15="","",N($G15)-N(R15))
B16: =IF($C16="","",COUNTA($C$9:$C16)) | O16: =IF($C16="","",N(L16)-N(M16)) | Q16: =IF($C16="","",N(M16)+N(N16)) | R16: =IF($C16="","",N(J16)+N(Q16)) | S16: =IF(OR($C16="",N($G16)=0),"",R16/$G16) | T16: =IF($C16="","",N($G16)-N(R16))
B17: =IF($C17="","",COUNTA($C$9:$C17)) | O17: =IF($C17="","",N(L17)-N(M17)) | Q17: =IF($C17="","",N(M17)+N(N17)) | R17: =IF($C17="","",N(J17)+N(Q17)) | S17: =IF(OR($C17="",N($G17)=0),"",R17/$G17) | T17: =IF($C17="","",N($G17)-N(R17))
B18: =IF($C18="","",COUNTA($C$9:$C18)) | O18: =IF($C18="","",N(L18)-N(M18)) | Q18: =IF($C18="","",N(M18)+N(N18)) | R18: =IF($C18="","",N(J18)+N(Q18)) | S18: =IF(OR($C18="",N($G18)=0),"",R18/$G18) | T18: =IF($C18="","",N($G18)-N(R18))
B19: =IF($C19="","",COUNTA($C$9:$C19)) | O19: =IF($C19="","",N(L19)-N(M19)) | Q19: =IF($C19="","",N(M19)+N(N19)) | R19: =IF($C19="","",N(J19)+N(Q19)) | S19: =IF(OR($C19="",N($G19)=0),"",R19/$G19) | T19: =IF($C19="","",N($G19)-N(R19))
B20: =IF($C20="","",COUNTA($C$9:$C20)) | O20: =IF($C20="","",N(L20)-N(M20)) | Q20: =IF($C20="","",N(M20)+N(N20)) | R20: =IF($C20="","",N(J20)+N(Q20)) | S20: =IF(OR($C20="",N($G20)=0),"",R20/$G20) | T20: =IF($C20="","",N($G20)-N(R20))
... B408: =IF($C408="","",COUNTA($C$9:$C408)) | O408: =IF($C408="","",N(L408)-N(M408)) | Q408: =IF($C408="","",N(M408)+N(N408)) | R408: =IF($C408="","",N(J408)+N(Q408)) | S408: =IF(OR($C408="",N($G408)=0),"",R408/$G408) | T408: =IF($C408="","",N($G408)-N(R408))

Sheet Piping
B2: JSW
C3: Piping — Backup Sheet (UOM: Inch-Mtr)
C4: =Config!$C$4
S5: Data date: | T5: =Config!$C$6
S6: Reporting date: | T6: =Config!$C$7
B7: SL. | C7: Name of the Structures | D7: Area | E7: Activity | F7: Agency / Contractor | G7: Scope | H7: Drawing Released | I7: Cum Front Available | J7: Achieved till last month | K7: Plan FTM | L7: Plan FTD | M7: Achieved FTD | N7: Achieved FTM till previous date | O7: Variance for the Day | P7: Reason(s) for Variance | Q7: Achieved FTM till date | R7: Workdone Till Date | S7: % Complete | T7: Balance | U7: Remarks | V7: Available Manpower
B8: a | C8: b | D8: c | E8: d | F8: e | G8: f | H8: g | I8: h | J8: i | K8: j | L8: k | M8: l | N8: m | O8: n = k-l | P8: o | Q8: p = l+m | R8: q = i+p | S8: r = (q/f)x100 | T8: s = f-q | U8: t | V8: u
B9: =IF($C9="","",COUNTA($C$9:$C9)) | O9: =IF($C9="","",N(L9)-N(M9)) | Q9: =IF($C9="","",N(M9)+N(N9)) | R9: =IF($C9="","",N(J9)+N(Q9)) | S9: =IF(OR($C9="",N($G9)=0),"",R9/$G9) | T9: =IF($C9="","",N($G9)-N(R9))
B10: =IF($C10="","",COUNTA($C$9:$C10)) | O10: =IF($C10="","",N(L10)-N(M10)) | Q10: =IF($C10="","",N(M10)+N(N10)) | R10: =IF($C10="","",N(J10)+N(Q10)) | S10: =IF(OR($C10="",N($G10)=0),"",R10/$G10) | T10: =IF($C10="","",N($G10)-N(R10))
B11: =IF($C11="","",COUNTA($C$9:$C11)) | O11: =IF($C11="","",N(L11)-N(M11)) | Q11: =IF($C11="","",N(M11)+N(N11)) | R11: =IF($C11="","",N(J11)+N(Q11)) | S11: =IF(OR($C11="",N($G11)=0),"",R11/$G11) | T11: =IF($C11="","",N($G11)-N(R11))
B12: =IF($C12="","",COUNTA($C$9:$C12)) | O12: =IF($C12="","",N(L12)-N(M12)) | Q12: =IF($C12="","",N(M12)+N(N12)) | R12: =IF($C12="","",N(J12)+N(Q12)) | S12: =IF(OR($C12="",N($G12)=0),"",R12/$G12) | T12: =IF($C12="","",N($G12)-N(R12))
B13: =IF($C13="","",COUNTA($C$9:$C13)) | O13: =IF($C13="","",N(L13)-N(M13)) | Q13: =IF($C13="","",N(M13)+N(N13)) | R13: =IF($C13="","",N(J13)+N(Q13)) | S13: =IF(OR($C13="",N($G13)=0),"",R13/$G13) | T13: =IF($C13="","",N($G13)-N(R13))
B14: =IF($C14="","",COUNTA($C$9:$C14)) | O14: =IF($C14="","",N(L14)-N(M14)) | Q14: =IF($C14="","",N(M14)+N(N14)) | R14: =IF($C14="","",N(J14)+N(Q14)) | S14: =IF(OR($C14="",N($G14)=0),"",R14/$G14) | T14: =IF($C14="","",N($G14)-N(R14))
B15: =IF($C15="","",COUNTA($C$9:$C15)) | O15: =IF($C15="","",N(L15)-N(M15)) | Q15: =IF($C15="","",N(M15)+N(N15)) | R15: =IF($C15="","",N(J15)+N(Q15)) | S15: =IF(OR($C15="",N($G15)=0),"",R15/$G15) | T15: =IF($C15="","",N($G15)-N(R15))
B16: =IF($C16="","",COUNTA($C$9:$C16)) | O16: =IF($C16="","",N(L16)-N(M16)) | Q16: =IF($C16="","",N(M16)+N(N16)) | R16: =IF($C16="","",N(J16)+N(Q16)) | S16: =IF(OR($C16="",N($G16)=0),"",R16/$G16) | T16: =IF($C16="","",N($G16)-N(R16))
B17: =IF($C17="","",COUNTA($C$9:$C17)) | O17: =IF($C17="","",N(L17)-N(M17)) | Q17: =IF($C17="","",N(M17)+N(N17)) | R17: =IF($C17="","",N(J17)+N(Q17)) | S17: =IF(OR($C17="",N($G17)=0),"",R17/$G17) | T17: =IF($C17="","",N($G17)-N(R17))
B18: =IF($C18="","",COUNTA($C$9:$C18)) | O18: =IF($C18="","",N(L18)-N(M18)) | Q18: =IF($C18="","",N(M18)+N(N18)) | R18: =IF($C18="","",N(J18)+N(Q18)) | S18: =IF(OR($C18="",N($G18)=0),"",R18/$G18) | T18: =IF($C18="","",N($G18)-N(R18))
B19: =IF($C19="","",COUNTA($C$9:$C19)) | O19: =IF($C19="","",N(L19)-N(M19)) | Q19: =IF($C19="","",N(M19)+N(N19)) | R19: =IF($C19="","",N(J19)+N(Q19)) | S19: =IF(OR($C19="",N($G19)=0),"",R19/$G19) | T19: =IF($C19="","",N($G19)-N(R19))
B20: =IF($C20="","",COUNTA($C$9:$C20)) | O20: =IF($C20="","",N(L20)-N(M20)) | Q20: =IF($C20="","",N(M20)+N(N20)) | R20: =IF($C20="","",N(J20)+N(Q20)) | S20: =IF(OR($C20="",N($G20)=0),"",R20/$G20) | T20: =IF($C20="","",N($G20)-N(R20))
... B408: =IF($C408="","",COUNTA($C$9:$C408)) | O408: =IF($C408="","",N(L408)-N(M408)) | Q408: =IF($C408="","",N(M408)+N(N408)) | R408: =IF($C408="","",N(J408)+N(Q408)) | S408: =IF(OR($C408="",N($G408)=0),"",R408/$G408) | T408: =IF($C408="","",N($G408)-N(R408))

Sheet Cable Trays (Km)
B2: JSW
C3: Cable Trays — Backup Sheet (UOM: Km)
C4: =Config!$C$4
S5: Data date: | T5: =Config!$C$6
S6: Reporting date: | T6: =Config!$C$7
B7: SL. | C7: Name of the Structures | D7: Area | E7: Activity | F7: Agency / Contractor | G7: Scope | H7: Drawing Released | I7: Cum Front Available | J7: Achieved till last month | K7: Plan FTM | L7: Plan FTD | M7: Achieved FTD | N7: Achieved FTM till previous date | O7: Variance for the Day | P7: Reason(s) for Variance | Q7: Achieved FTM till date | R7: Workdone Till Date | S7: % Complete | T7: Balance | U7: Remarks | V7: Available Manpower
B8: a | C8: b | D8: c | E8: d | F8: e | G8: f | H8: g | I8: h | J8: i | K8: j | L8: k | M8: l | N8: m | O8: n = k-l | P8: o | Q8: p = l+m | R8: q = i+p | S8: r = (q/f)x100 | T8: s = f-q | U8: t | V8: u
B9: =IF($C9="","",COUNTA($C$9:$C9)) | O9: =IF($C9="","",N(L9)-N(M9)) | Q9: =IF($C9="","",N(M9)+N(N9)) | R9: =IF($C9="","",N(J9)+N(Q9)) | S9: =IF(OR($C9="",N($G9)=0),"",R9/$G9) | T9: =IF($C9="","",N($G9)-N(R9))
B10: =IF($C10="","",COUNTA($C$9:$C10)) | O10: =IF($C10="","",N(L10)-N(M10)) | Q10: =IF($C10="","",N(M10)+N(N10)) | R10: =IF($C10="","",N(J10)+N(Q10)) | S10: =IF(OR($C10="",N($G10)=0),"",R10/$G10) | T10: =IF($C10="","",N($G10)-N(R10))
B11: =IF($C11="","",COUNTA($C$9:$C11)) | O11: =IF($C11="","",N(L11)-N(M11)) | Q11: =IF($C11="","",N(M11)+N(N11)) | R11: =IF($C11="","",N(J11)+N(Q11)) | S11: =IF(OR($C11="",N($G11)=0),"",R11/$G11) | T11: =IF($C11="","",N($G11)-N(R11))
B12: =IF($C12="","",COUNTA($C$9:$C12)) | O12: =IF($C12="","",N(L12)-N(M12)) | Q12: =IF($C12="","",N(M12)+N(N12)) | R12: =IF($C12="","",N(J12)+N(Q12)) | S12: =IF(OR($C12="",N($G12)=0),"",R12/$G12) | T12: =IF($C12="","",N($G12)-N(R12))
B13: =IF($C13="","",COUNTA($C$9:$C13)) | O13: =IF($C13="","",N(L13)-N(M13)) | Q13: =IF($C13="","",N(M13)+N(N13)) | R13: =IF($C13="","",N(J13)+N(Q13)) | S13: =IF(OR($C13="",N($G13)=0),"",R13/$G13) | T13: =IF($C13="","",N($G13)-N(R13))
B14: =IF($C14="","",COUNTA($C$9:$C14)) | O14: =IF($C14="","",N(L14)-N(M14)) | Q14: =IF($C14="","",N(M14)+N(N14)) | R14: =IF($C14="","",N(J14)+N(Q14)) | S14: =IF(OR($C14="",N($G14)=0),"",R14/$G14) | T14: =IF($C14="","",N($G14)-N(R14))
B15: =IF($C15="","",COUNTA($C$9:$C15)) | O15: =IF($C15="","",N(L15)-N(M15)) | Q15: =IF($C15="","",N(M15)+N(N15)) | R15: =IF($C15="","",N(J15)+N(Q15)) | S15: =IF(OR($C15="",N($G15)=0),"",R15/$G15) | T15: =IF($C15="","",N($G15)-N(R15))
B16: =IF($C16="","",COUNTA($C$9:$C16)) | O16: =IF($C16="","",N(L16)-N(M16)) | Q16: =IF($C16="","",N(M16)+N(N16)) | R16: =IF($C16="","",N(J16)+N(Q16)) | S16: =IF(OR($C16="",N($G16)=0),"",R16/$G16) | T16: =IF($C16="","",N($G16)-N(R16))
B17: =IF($C17="","",COUNTA($C$9:$C17)) | O17: =IF($C17="","",N(L17)-N(M17)) | Q17: =IF($C17="","",N(M17)+N(N17)) | R17: =IF($C17="","",N(J17)+N(Q17)) | S17: =IF(OR($C17="",N($G17)=0),"",R17/$G17) | T17: =IF($C17="","",N($G17)-N(R17))
B18: =IF($C18="","",COUNTA($C$9:$C18)) | O18: =IF($C18="","",N(L18)-N(M18)) | Q18: =IF($C18="","",N(M18)+N(N18)) | R18: =IF($C18="","",N(J18)+N(Q18)) | S18: =IF(OR($C18="",N($G18)=0),"",R18/$G18) | T18: =IF($C18="","",N($G18)-N(R18))
B19: =IF($C19="","",COUNTA($C$9:$C19)) | O19: =IF($C19="","",N(L19)-N(M19)) | Q19: =IF($C19="","",N(M19)+N(N19)) | R19: =IF($C19="","",N(J19)+N(Q19)) | S19: =IF(OR($C19="",N($G19)=0),"",R19/$G19) | T19: =IF($C19="","",N($G19)-N(R19))
B20: =IF($C20="","",COUNTA($C$9:$C20)) | O20: =IF($C20="","",N(L20)-N(M20)) | Q20: =IF($C20="","",N(M20)+N(N20)) | R20: =IF($C20="","",N(J20)+N(Q20)) | S20: =IF(OR($C20="",N($G20)=0),"",R20/$G20) | T20: =IF($C20="","",N($G20)-N(R20))
... B408: =IF($C408="","",COUNTA($C$9:$C408)) | O408: =IF($C408="","",N(L408)-N(M408)) | Q408: =IF($C408="","",N(M408)+N(N408)) | R408: =IF($C408="","",N(J408)+N(Q408)) | S408: =IF(OR($C408="",N($G408)=0),"",R408/$G408) | T408: =IF($C408="","",N($G408)-N(R408))

Sheet Cabling (Km)
B2: JSW
C3: Cabling — Backup Sheet (UOM: Km)
C4: =Config!$C$4
S5: Data date: | T5: =Config!$C$6
S6: Reporting date: | T6: =Config!$C$7
B7: SL. | C7: Name of the Structures | D7: Area | E7: Activity | F7: Agency / Contractor | G7: Scope | H7: Drawing Released | I7: Cum Front Available | J7: Achieved till last month | K7: Plan FTM | L7: Plan FTD | M7: Achieved FTD | N7: Achieved FTM till previous date | O7: Variance for the Day | P7: Reason(s) for Variance | Q7: Achieved FTM till date | R7: Workdone Till Date | S7: % Complete | T7: Balance | U7: Remarks | V7: Available Manpower
B8: a | C8: b | D8: c | E8: d | F8: e | G8: f | H8: g | I8: h | J8: i | K8: j | L8: k | M8: l | N8: m | O8: n = k-l | P8: o | Q8: p = l+m | R8: q = i+p | S8: r = (q/f)x100 | T8: s = f-q | U8: t | V8: u
B9: =IF($C9="","",COUNTA($C$9:$C9)) | O9: =IF($C9="","",N(L9)-N(M9)) | Q9: =IF($C9="","",N(M9)+N(N9)) | R9: =IF($C9="","",N(J9)+N(Q9)) | S9: =IF(OR($C9="",N($G9)=0),"",R9/$G9) | T9: =IF($C9="","",N($G9)-N(R9))
B10: =IF($C10="","",COUNTA($C$9:$C10)) | O10: =IF($C10="","",N(L10)-N(M10)) | Q10: =IF($C10="","",N(M10)+N(N10)) | R10: =IF($C10="","",N(J10)+N(Q10)) | S10: =IF(OR($C10="",N($G10)=0),"",R10/$G10) | T10: =IF($C10="","",N($G10)-N(R10))
B11: =IF($C11="","",COUNTA($C$9:$C11)) | O11: =IF($C11="","",N(L11)-N(M11)) | Q11: =IF($C11="","",N(M11)+N(N11)) | R11: =IF($C11="","",N(J11)+N(Q11)) | S11: =IF(OR($C11="",N($G11)=0),"",R11/$G11) | T11: =IF($C11="","",N($G11)-N(R11))
B12: =IF($C12="","",COUNTA($C$9:$C12)) | O12: =IF($C12="","",N(L12)-N(M12)) | Q12: =IF($C12="","",N(M12)+N(N12)) | R12: =IF($C12="","",N(J12)+N(Q12)) | S12: =IF(OR($C12="",N($G12)=0),"",R12/$G12) | T12: =IF($C12="","",N($G12)-N(R12))
B13: =IF($C13="","",COUNTA($C$9:$C13)) | O13: =IF($C13="","",N(L13)-N(M13)) | Q13: =IF($C13="","",N(M13)+N(N13)) | R13: =IF($C13="","",N(J13)+N(Q13)) | S13: =IF(OR($C13="",N($G13)=0),"",R13/$G13) | T13: =IF($C13="","",N($G13)-N(R13))
B14: =IF($C14="","",COUNTA($C$9:$C14)) | O14: =IF($C14="","",N(L14)-N(M14)) | Q14: =IF($C14="","",N(M14)+N(N14)) | R14: =IF($C14="","",N(J14)+N(Q14)) | S14: =IF(OR($C14="",N($G14)=0),"",R14/$G14) | T14: =IF($C14="","",N($G14)-N(R14))
B15: =IF($C15="","",COUNTA($C$9:$C15)) | O15: =IF($C15="","",N(L15)-N(M15)) | Q15: =IF($C15="","",N(M15)+N(N15)) | R15: =IF($C15="","",N(J15)+N(Q15)) | S15: =IF(OR($C15="",N($G15)=0),"",R15/$G15) | T15: =IF($C15="","",N($G15)-N(R15))
B16: =IF($C16="","",COUNTA($C$9:$C16)) | O16: =IF($C16="","",N(L16)-N(M16)) | Q16: =IF($C16="","",N(M16)+N(N16)) | R16: =IF($C16="","",N(J16)+N(Q16)) | S16: =IF(OR($C16="",N($G16)=0),"",R16/$G16) | T16: =IF($C16="","",N($G16)-N(R16))
B17: =IF($C17="","",COUNTA($C$9:$C17)) | O17: =IF($C17="","",N(L17)-N(M17)) | Q17: =IF($C17="","",N(M17)+N(N17)) | R17: =IF($C17="","",N(J17)+N(Q17)) | S17: =IF(OR($C17="",N($G17)=0),"",R17/$G17) | T17: =IF($C17="","",N($G17)-N(R17))
B18: =IF($C18="","",COUNTA($C$9:$C18)) | O18: =IF($C18="","",N(L18)-N(M18)) | Q18: =IF($C18="","",N(M18)+N(N18)) | R18: =IF($C18="","",N(J18)+N(Q18)) | S18: =IF(OR($C18="",N($G18)=0),"",R18/$G18) | T18: =IF($C18="","",N($G18)-N(R18))
B19: =IF($C19="","",COUNTA($C$9:$C19)) | O19: =IF($C19="","",N(L19)-N(M19)) | Q19: =IF($C19="","",N(M19)+N(N19)) | R19: =IF($C19="","",N(J19)+N(Q19)) | S19: =IF(OR($C19="",N($G19)=0),"",R19/$G19) | T19: =IF($C19="","",N($G19)-N(R19))
B20: =IF($C20="","",COUNTA($C$9:$C20)) | O20: =IF($C20="","",N(L20)-N(M20)) | Q20: =IF($C20="","",N(M20)+N(N20)) | R20: =IF($C20="","",N(J20)+N(Q20)) | S20: =IF(OR($C20="",N($G20)=0),"",R20/$G20) | T20: =IF($C20="","",N($G20)-N(R20))
... B408: =IF($C408="","",COUNTA($C$9:$C408)) | O408: =IF($C408="","",N(L408)-N(M408)) | Q408: =IF($C408="","",N(M408)+N(N408)) | R408: =IF($C408="","",N(J408)+N(Q408)) | S408: =IF(OR($C408="",N($G408)=0),"",R408/$G408) | T408: =IF($C408="","",N($G408)-N(R408))

Sheet Panels (Nos)
B2: JSW
C3: Panels — Backup Sheet (UOM: Nos)
C4: =Config!$C$4
S5: Data date: | T5: =Config!$C$6
S6: Reporting date: | T6: =Config!$C$7
B7: SL. | C7: Name of the Structures | D7: Area | E7: Activity | F7: Agency / Contractor | G7: Scope | H7: Drawing Released | I7: Cum Front Available | J7: Achieved till last month | K7: Plan FTM | L7: Plan FTD | M7: Achieved FTD | N7: Achieved FTM till previous date | O7: Variance for the Day | P7: Reason(s) for Variance | Q7: Achieved FTM till date | R7: Workdone Till Date | S7: % Complete | T7: Balance | U7: Remarks | V7: Available Manpower
B8: a | C8: b | D8: c | E8: d | F8: e | G8: f | H8: g | I8: h | J8: i | K8: j | L8: k | M8: l | N8: m | O8: n = k-l | P8: o | Q8: p = l+m | R8: q = i+p | S8: r = (q/f)x100 | T8: s = f-q | U8: t | V8: u
B9: =IF($C9="","",COUNTA($C$9:$C9)) | O9: =IF($C9="","",N(L9)-N(M9)) | Q9: =IF($C9="","",N(M9)+N(N9)) | R9: =IF($C9="","",N(J9)+N(Q9)) | S9: =IF(OR($C9="",N($G9)=0),"",R9/$G9) | T9: =IF($C9="","",N($G9)-N(R9))
B10: =IF($C10="","",COUNTA($C$9:$C10)) | O10: =IF($C10="","",N(L10)-N(M10)) | Q10: =IF($C10="","",N(M10)+N(N10)) | R10: =IF($C10="","",N(J10)+N(Q10)) | S10: =IF(OR($C10="",N($G10)=0),"",R10/$G10) | T10: =IF($C10="","",N($G10)-N(R10))
B11: =IF($C11="","",COUNTA($C$9:$C11)) | O11: =IF($C11="","",N(L11)-N(M11)) | Q11: =IF($C11="","",N(M11)+N(N11)) | R11: =IF($C11="","",N(J11)+N(Q11)) | S11: =IF(OR($C11="",N($G11)=0),"",R11/$G11) | T11: =IF($C11="","",N($G11)-N(R11))
B12: =IF($C12="","",COUNTA($C$9:$C12)) | O12: =IF($C12="","",N(L12)-N(M12)) | Q12: =IF($C12="","",N(M12)+N(N12)) | R12: =IF($C12="","",N(J12)+N(Q12)) | S12: =IF(OR($C12="",N($G12)=0),"",R12/$G12) | T12: =IF($C12="","",N($G12)-N(R12))
B13: =IF($C13="","",COUNTA($C$9:$C13)) | O13: =IF($C13="","",N(L13)-N(M13)) | Q13: =IF($C13="","",N(M13)+N(N13)) | R13: =IF($C13="","",N(J13)+N(Q13)) | S13: =IF(OR($C13="",N($G13)=0),"",R13/$G13) | T13: =IF($C13="","",N($G13)-N(R13))
B14: =IF($C14="","",COUNTA($C$9:$C14)) | O14: =IF($C14="","",N(L14)-N(M14)) | Q14: =IF($C14="","",N(M14)+N(N14)) | R14: =IF($C14="","",N(J14)+N(Q14)) | S14: =IF(OR($C14="",N($G14)=0),"",R14/$G14) | T14: =IF($C14="","",N($G14)-N(R14))
B15: =IF($C15="","",COUNTA($C$9:$C15)) | O15: =IF($C15="","",N(L15)-N(M15)) | Q15: =IF($C15="","",N(M15)+N(N15)) | R15: =IF($C15="","",N(J15)+N(Q15)) | S15: =IF(OR($C15="",N($G15)=0),"",R15/$G15) | T15: =IF($C15="","",N($G15)-N(R15))
B16: =IF($C16="","",COUNTA($C$9:$C16)) | O16: =IF($C16="","",N(L16)-N(M16)) | Q16: =IF($C16="","",N(M16)+N(N16)) | R16: =IF($C16="","",N(J16)+N(Q16)) | S16: =IF(OR($C16="",N($G16)=0),"",R16/$G16) | T16: =IF($C16="","",N($G16)-N(R16))
B17: =IF($C17="","",COUNTA($C$9:$C17)) | O17: =IF($C17="","",N(L17)-N(M17)) | Q17: =IF($C17="","",N(M17)+N(N17)) | R17: =IF($C17="","",N(J17)+N(Q17)) | S17: =IF(OR($C17="",N($G17)=0),"",R17/$G17) | T17: =IF($C17="","",N($G17)-N(R17))
B18: =IF($C18="","",COUNTA($C$9:$C18)) | O18: =IF($C18="","",N(L18)-N(M18)) | Q18: =IF($C18="","",N(M18)+N(N18)) | R18: =IF($C18="","",N(J18)+N(Q18)) | S18: =IF(OR($C18="",N($G18)=0),"",R18/$G18) | T18: =IF($C18="","",N($G18)-N(R18))
B19: =IF($C19="","",COUNTA($C$9:$C19)) | O19: =IF($C19="","",N(L19)-N(M19)) | Q19: =IF($C19="","",N(M19)+N(N19)) | R19: =IF($C19="","",N(J19)+N(Q19)) | S19: =IF(OR($C19="",N($G19)=0),"",R19/$G19) | T19: =IF($C19="","",N($G19)-N(R19))
B20: =IF($C20="","",COUNTA($C$9:$C20)) | O20: =IF($C20="","",N(L20)-N(M20)) | Q20: =IF($C20="","",N(M20)+N(N20)) | R20: =IF($C20="","",N(J20)+N(Q20)) | S20: =IF(OR($C20="",N($G20)=0),"",R20/$G20) | T20: =IF($C20="","",N($G20)-N(R20))
... B408: =IF($C408="","",COUNTA($C$9:$C408)) | O408: =IF($C408="","",N(L408)-N(M408)) | Q408: =IF($C408="","",N(M408)+N(N408)) | R408: =IF($C408="","",N(J408)+N(Q408)) | S408: =IF(OR($C408="",N($G408)=0),"",R408/$G408) | T408: =IF($C408="","",N($G408)-N(R408))

Sheet Manpower
B2: JSW
C3: Manpower Deployment — Backup Sheet
C4: =Config!$C$4
F5: Data date: | G5: =Config!$C$6
F6: Reporting date: | G6: =Config!$C$7
B7: SL. | C7: Area | D7: Agency / Contractor | E7: Category | F7: Planned (Nos) | G7: Actual / Available (Nos) | H7: Variance | I7: Remarks
B8: a | C8: b | D8: c | E8: d | F8: e | G8: f | H8: g = f-e | I8: h
B9: =IF($C9="","",COUNTA($C$9:$C9)) | H9: =IF($C9="","",N(F9)-N(E9))
B10: =IF($C10="","",COUNTA($C$9:$C10)) | H10: =IF($C10="","",N(F10)-N(E10))
B11: =IF($C11="","",COUNTA($C$9:$C11)) | H11: =IF($C11="","",N(F11)-N(E11))
B12: =IF($C12="","",COUNTA($C$9:$C12)) | H12: =IF($C12="","",N(F12)-N(E12))
B13: =IF($C13="","",COUNTA($C$9:$C13)) | H13: =IF($C13="","",N(F13)-N(E13))
B14: =IF($C14="","",COUNTA($C$9:$C14)) | H14: =IF($C14="","",N(F14)-N(E14))
B15: =IF($C15="","",COUNTA($C$9:$C15)) | H15: =IF($C15="","",N(F15)-N(E15))
B16: =IF($C16="","",COUNTA($C$9:$C16)) | H16: =IF($C16="","",N(F16)-N(E16))
B17: =IF($C17="","",COUNTA($C$9:$C17)) | H17: =IF($C17="","",N(F17)-N(E17))
B18: =IF($C18="","",COUNTA($C$9:$C18)) | H18: =IF($C18="","",N(F18)-N(E18))
B19: =IF($C19="","",COUNTA($C$9:$C19)) | H19: =IF($C19="","",N(F19)-N(E19))
B20: =IF($C20="","",COUNTA($C$9:$C20)) | H20: =IF($C20="","",N(F20)-N(E20))
... B308: =IF($C308="","",COUNTA($C$9:$C308)) | H308: =IF($C308="","",N(F308)-N(E308))

Sheet Vendor-Import
B2: VENDOR IMPORT — staging area
B3: Paste the normalised rows exported by dpr_consolidator.html here (or paste vendor data and fix the 4 green key columns by hand). Then copy the block into the matching discipline sheet.
B5: Discipline (sheet) | C5: Name of the Structures | D5: Area | E5: Activity | F5: Agency / Contractor | G5: Scope | H5: Drawing Released | I5: Cum Front Available | J5: Achieved till last month | K5: Plan FTM | L5: Plan FTD | M5: Achieved FTD | N5: Achieved FTM till previous date | O5: Reason(s) for Variance | P5: Remarks | Q5: Available Manpower

Sheet Mapping
B2: COLUMN SYNONYM DICTIONARY (auto-mapping of vendor headers)
B3: Add any new header wording your vendors use, separated by ' | '. The HTML consolidator reads the very same list, so keep the two in step.
B5: Canonical field | C5: Standard header | D5: Accepted vendor headings (| separated)
B6: structure | C6: Name of the Structures | D6: name of structure | structure | description | activity description | item | work description | particulars | building | location | element
B7: area | C7: Area | D7: area | zone | unit | block | package | plant area | section
B8: activity | C8: Activity | D8: activity | discipline | work type | sub head | category of work
B9: agency | C9: Agency / Contractor | D9: agency | contractor | vendor | sub contractor | agency/contractor | executing agency | party
B10: scope | C10: Scope | D10: scope | total scope | total qty | boq qty | contract qty | ordered qty | total quantity
B11: drawing | C11: Drawing Released | D11: drawing released | drg released | drawings issued | gfc released | ifc released
B12: front | C12: Cum Front Available | D12: front available | cum front available | front | fronts released | work front
B13: last_month | C13: Achieved till last month | D13: achieved till last month | cum till last month | upto last month | progress till last month | opening balance
B14: plan_ftm | C14: Plan FTM | D14: plan ftm | plan for the month | monthly plan | mtd plan | target for month | plan month
B15: plan_ftd | C15: Plan FTD | D15: plan ftd | plan for the day | daily plan | today plan | dpr plan | plan today
