Workbook

Sheet Read Me
B1: CHILLER PLANT – 4D BIM CONSTRUCTION SCHEDULE
B2: JSW Utkal Steel Ltd – 816 m² Pelletizing Plant-1 (PP-1), Paradeep, Odisha | Chiller Plant (combined for PP-1 & PP-2)
B3: Owner: JSW Utkal Steel Ltd | Technology: Primetals Technologies | Engineering & construction partner: L&T Construction (Minerals & Metals)
B5: GENERAL
B6: P6 reference schedule | C6: NEWPROJ-24_DD_2026-10-02_6.xer (and Schedule Engine export NEWPROJ-24_DD_2026-10-02_3_1.xlsx) – WBS Pellet Plant-1 › Utilities › Chiller Plant (19 activities)
B7: Data Date (input) | C7: 46297 | D7: ← change for every progress update (all sheets follow)
B8: Next working day (formula) | C8: =INDEX(WorkDays,MATCH(DataDate,WorkDays,1)+1) -> 46298
B9: Calendar | C9: JSW USL Calender – Mon–Sat working, Sunday off, 10 h/day, holidays per XER (see Calendar sheet)
B11: SHEETS
B12: 4D Schedule | C12: Hierarchy = P6: Lvl 1 Chiller Plant › Lvl 2 Engineering / Procurement / Construction › Lvl 3 GROUP = each of the 18 P6 activities (dates identical to P6 for baseline, actual & current) › Lvl 4 = 126 detailed activities sequenced inside their group (+ 2 groups of additional scope not in P6). Each construction activity carries BIM category, element marks, zone, level, drawing, selection set and TimeLiner task type.
B13: BIM Element Map | C13: 411 model elements (53 piles, 35 pile caps, 29 pile cap beams, 116 column segments, plinth/floor/roof beams & slabs, stairs, trenches, F1/F2 foundations, equipment …) each linked to one 4D activity, with live dates & status.
B14: TimeLiner Import | C14: Flat, CSV-ready task table for Navisworks TimeLiner / Synchro / Fuzor (also delivered as a separate .csv). Planned = current schedule, Actual = site actuals, Baseline = P6 BL.
B15: Gantt | C15: Weekly bar chart of the current schedule with data-date line (conditional formatting – updates automatically).
B16: P6 Roll-up | C16: For every P6 activity: P6 BL / current / actual dates vs the group roll-up in the 4D Schedule (Δ in working days, "✔ Same as P6") + progress summary (activities, elements, RCC quantity).
B17: Calendar | C17: Working-day list (named range WorkDays) and holidays from the XER.
B19: HOW TO UPDATE (monthly / weekly)
B20: 1. Set the new Data Date in C7.
B21: 2. In 4D Schedule enter Actual Start / Actual Finish / % Complete (yellow cells) from DPR, pour cards and pile register. Replace the blue ASSUMED actual dates with real ones.
B22: 3. Current Start/Finish of all remaining activities re-plan automatically (Pred-1/Pred-2 logic, FS/SS + lag in working days, SNET, project calendar). Change durations, logic or SNET in the blue cells if the site sequence differs.
B23: 4. Check P6 Roll-up: detailed finish dates should match the updated P6 dates (Δ = 0) – otherwise adjust durations / SNET or report the variance.
B24: 5. Re-export TimeLiner Import (File › Save As › CSV) or refresh the Excel/CSV data source in Navisworks / Synchro and re-run the simulation.
B26: HOW TO LINK WITH THE BIM MODEL (4D)
B27: A. Revit / Tekla: create text parameters 4D_Element_ID and 4D_Activity_ID (shared, instance) on all categories used. Fill them from BIM Element Map (columns A & J) – e.g. Dynamo "Data.ImportExcel" + "Element.SetParameterByName", or Tekla UDA import. Split columns at EL -0.300 / +4.000 / +9.150 (construction joints) so each lift is a separate element.
B28: B. Navisworks: append the model (NWC), TimeLiner › Data Sources › Add › CSV Import (TimeLiner Import .csv) – map Display ID, Task Name, Task Type, Planned Start/End, Actual Start/End; Rebuild Task Hierarchy.
B29: C. TimeLiner › Auto-Attach Using Rules › New rule: "Map TimeLiner tasks from column Display ID to items with property 4D_Activity_ID (category Element)". Alternatively create Search Sets named exactly as the Activity ID (column J of 4D Schedule) and use the "Selection Sets with the same name" rule.
B30: D. Simulate › Settings: show Planned vs Actual (Actual dates = site actuals; Planned = current schedule; Baseline columns can be mapped to Planned for BL-vs-actual comparison). Task types: Construct (appear), Demolish (excavation – disappear), Temporary.
B31: E. Synchro 4D / Fuzor: import the same CSV / Excel, link resources by the 4D_Activity_ID user field.
... B43: COLOUR LEGEND
C44: Site input cell (Actual Start / Finish / % Complete, Data Date)
B45: Abc | C45: Blue text = input / assumed value (logic, durations, SNET, assumed actuals)
C46: Lvl 3 GROUP row = P6 activity (roll-up = P6 dates)
C47: Lvl 2 phase row (Engineering / Procurement / Construction)
C48: Milestone
C49: Status Completed
C50: Status In Progress
C51: Not Started (Late) – baseline start already passed
B53: DRAWINGS USED
B54: O24091-990-C-B-19530-001 | C54: R0 | D54: Chiller Plant – Layout & detail of pile (P1–P53, 600Ø bored cast-in-situ, L = 26 m)
B55: O24091-990-C-B-19531-001 | C55: R0 | D55: Layout & detail of pile cap (PC1 ×17, PC2 ×18), pile cap beam (PCB1/2/3) & column schedule (C1–C9, SC1)
B56: O24091-990-C-B-19531-002 | C56: R0 | D56: GA & RC detail of plinth beam (PB1–PB10) at EL(-)0.300 TOB
...

Sheet 4D Schedule
A1: CHILLER PLANT (Combined for PP-1 & PP-2) – 4D BIM CONSTRUCTION SCHEDULE (detailed, element-linked)
A2: JSW Utkal Steel Ltd – 816 m² Pelletizing Plant-1 (PP-1), Paradeep | P6 reference: NEWPROJ-24 (XER, Data Date 02-Oct-2026), WBS Pellet Plant-1 › Utilities › Chiller Plant | Drawings O24091-990-C-B-19530-001 & 19531-001…008 (R0) | AD2: Data Date: | AE2: =DataDate -> 46297
A3: Structure: Lvl 1 project › Lvl 2 phase › Lvl 3 GROUP = P6 activity (dates = P6 BL / actual / current) › Lvl 4 detailed activities sequenced inside the group. Yellow = site input (Actual Start / Finish / % Complete); blue text = assumed / logic inputs. Use outline buttons 1–4 (left margin) to collapse to group level.
A4: ACTIVITY | E4: BIM / 4D LINK | N4: P6 GROUP & QUANTITY | Q4: LOGIC (working days) | Y4: BASELINE (P6 BL) | AA4: ACTUAL – SITE INPUT | AD4: CURRENT SCHEDULE | AG4: ANALYSIS
A5: Activity ID / P6 Group | B5: Lvl | C5: Activity Name | D5: Work Package | E5: Zone | F5: Grid / Location | G5: Level / Elevation | H5: BIM Category | I5: Element Marks | J5: No. of BIM Elements | K5: Selection / Search Set (TimeLiner) | L5: TimeLiner Task Type | M5: Drawing Ref. | N5: P6 Group (parent) | O5: Qty (approx) | P5: Unit | Q5: Orig Dur (wd) | R5: Pred-1 | S5: Rel-1 | T5: Lag-1 (wd) | U5: Pred-2 | V5: Rel-2 | W5: Lag-2 (wd) | X5: Start No Earlier Than | Y5: BL Start | Z5: BL Finish | AA5: Actual Start | AB5: Actual Finish | AC5: % Complete | AD5: Remaining Dur (wd) | AE5: Current Start | AF5: Current Finish | AG5: Status | AH5: Finish Var vs BL (wd, + = late) | AI5: Qty Done | AJ5: Remarks / P6 check
A6: CHP | B6: 1 | C6: CHILLER PLANT (combined for PP-1 & PP-2) – P6 WBS: Pellet Plant-1 › Utilities › Chiller Plant | J6: =SUMIF($B$7:$B$156,4,$J$7:$J$156) -> 411 | Y6: =MIN($Y$7:$Y$156) -> 46042 | Z6: =MAX($Z$7:$Z$156) -> 46522 | AA6: =IF(COUNT($AA$7:$AA$156)=0,"",MIN($AA$7:$AA$156)) -> 45950 | AB6: =IF(COUNTIFS($B$7:$B$156,4,$AG$7:$AG$156,"Completed")=COUNTIF($B$7:$B$156,4),MAX($AB$7:$AB$156),"") | AC6: =IFERROR(IFERROR(SUMPRODUCT(--($B$7:$B$156=4),$Q$7:$Q$156,$AC$7:$AC$156)/SUMIF($B$7:$B$156,4,$Q$7:$Q$156),AVERAGEIF($B$7:$B$156,4,$AC$7:$AC$156)),"") -> 0.52619263 | AE6: =MIN($AE$7:$AE$156) -> 45950 | AF6: =MAX($AF$7:$AF$156) -> 46510 | AG6: =IF(COUNTIFS($B$7:$B$156,4,$AG$7:$AG$156,"Completed")=COUNTIF($B$7:$B$156,4),"Completed",IF(COUNTIFS($B$7:$B$156,4,$AG$7:$AG$156,"Not Started*")=COUNTIF($B$7:$B$156,4),"Not Started","In Progress")) -> In Progress | AH6: =MATCH($AF6,WorkDays,1)-MATCH($Z6,WorkDays,1) -> -11
A7: CHP.E | B7: 2 | C7: ENGINEERING | J7: =SUMIF($B$8:$B$29,4,$J$8:$J$29) -> 0 | Y7: =MIN($Y$8:$Y$29) -> 46042 | Z7: =MAX($Z$8:$Z$29) -> 46396 | AA7: =IF(COUNT($AA$8:$AA$29)=0,"",MIN($AA$8:$AA$29)) -> 45950 | AB7: =IF(COUNTIFS($B$8:$B$29,4,$AG$8:$AG$29,"Completed")=COUNTIF($B$8:$B$29,4),MAX($AB$8:$AB$29),"") | AC7: =IFERROR(IFERROR(SUMPRODUCT(--($B$8:$B$29=4),$Q$8:$Q$29,$AC$8:$AC$29)/SUMIF($B$8:$B$29,4,$Q$8:$Q$29),AVERAGEIF($B$8:$B$29,4,$AC$8:$AC$29)),"") -> 0.45734266 | AE7: =MIN($AE$8:$AE$29) -> 45950 | AF7: =MAX($AF$8:$AF$29) -> 46367 | AG7: =IF(COUNTIFS($B$8:$B$29,4,$AG$8:$AG$29,"Completed")=COUNTIF($B$8:$B$29,4),"Completed",IF(COUNTIFS($B$8:$B$29,4,$AG$8:$AG$29,"Not Started*")=COUNTIF($B$8:$B$29,4),"Not Started","In Progress")) -> In Progress | AH7: =MATCH($AF7,WorkDays,1)-MATCH($Z7,WorkDays,1) -> -23
A8: JSW USL-BE-CHI-1000 | B8: 3 | C8: Basic drawings from TS - Inputs | J8: =SUMIF($B$9:$B$9,4,$J$9:$J$9) -> 0 | O8: =IF(SUMIF($B$9:$B$9,4,$O$9:$O$9)=0,"",SUMIF($B$9:$B$9,4,$O$9:$O$9)) | Y8: =MIN($Y$9:$Y$9) -> 46042 | Z8: =MAX($Z$9:$Z$9) -> 46042 | AA8: =IF(COUNT($AA$9:$AA$9)=0,"",MIN($AA$9:$AA$9)) -> 45950 | AB8: =IF(COUNTIFS($B$9:$B$9,4,$AG$9:$AG$9,"Completed")=COUNTIF($B$9:$B$9,4),MAX($AB$9:$AB$9),"") -> 45950 | AC8: =IFERROR(IF(SUMIF($B$9:$B$9,4,$O$9:$O$9)>0,SUMIF($B$9:$B$9,4,$AI$9:$AI$9)/SUMIF($B$9:$B$9,4,$O$9:$O$9),IFERROR(SUMPRODUCT(--($B$9:$B$9=4),$Q$9:$Q$9,$AC$9:$AC$9)/SUMIF($B$9:$B$9,4,$Q$9:$Q$9),AVERAGEIF($B$9:$B$9,4,$AC$9:$AC$9))),"") -> 1 | AE8: =MIN($AE$9:$AE$9) -> 45950 | AF8: =MAX($AF$9:$AF$9) -> 45950 | AG8: =IF(COUNTIFS($B$9:$B$9,4,$AG$9:$AG$9,"Completed")=COUNTIF($B$9:$B$9,4),"Completed",IF(COUNTIFS($B$9:$B$9,4,$AG$9:$AG$9,"Not Started*")=COUNTIF($B$9:$B$9,4),"Not Started","In Progress")) -> Completed | AH8: =MATCH($AF8,WorkDays,1)-MATCH($Z8,WorkDays,1) -> -77 | AI8: =IF(SUMIF($B$9:$B$9,4,$O$9:$O$9)=0,"",SUMIF($B$9:$B$9,4,$AI$9:$AI$9)) | AJ8: ="P6 check: "&INDEX('P6 Roll-up'!$AB$5:$AB$22,MATCH($A8,'P6 Roll-up'!$A$5:$A$22,0)) -> P6 check: ✔ Same as P6
A9: CHP-MS-010 | B9: 4 | C9: Basic drawings / technical specification inputs received | D9: Milestone | H9: — (non-BIM milestone) | J9: =COUNTIF('BIM Element Map'!$J$6:$J$1000,$A9) -> 0 | L9: Milestone | N9: JSW USL-BE-CHI-1000 | Q9: 0 | Y9: 46042 | Z9: 46042 | AA9: 45950 | AB9: 45950 | AC9: 1 | AD9: =IF($AB9<>"",0,IF($AA9="",$Q9,MAX(1,ROUND($Q9*(1-$AC9),0)))) -> 0 | AE9: =IF($AA9<>"",$AA9,MAX($X9,NextWD,IF($R9="",0,IF($S9="SS",INDEX(WorkDays,MATCH(INDEX($AE$6:$AE$156,MATCH($R9,$A$6:$A$156,0))-1,WorkDays,1)+1+$T9),INDEX(WorkDays,MATCH(INDEX($AF$6:$AF$156,MATCH($R9,$A$6:$A$156,0)),WorkDays,1)+IF($Q9=0,0,1)+$T9))),IF($U9="",0,IF($V9="SS",INDEX(WorkDays,MATCH(INDEX($AE$6:$AE$156,MATCH($U9,$A$6:$A$156,0))-1,WorkDays,1)+1+$W9),INDEX(WorkDays,MATCH(INDEX($AF$6:$AF$156,MATCH($U9,$A$6:$A$156,0)),WorkDays,1)+IF($Q9=0,0,1)+$W9))))) -> 45950 | AF9: =IF($AB9<>"",$AB9,IF($Q9=0,$AE9,INDEX(WorkDays,MATCH(MAX($AE9,NextWD)-1,WorkDays,1)+$AD9))) -> 45950 | AG9: =IF($AB9<>"","Completed",IF($AA9<>"","In Progress",IF(AND($Y9<>"",$Y9<=DataDate),"Not Started (Late)","Not Started"))) -> Completed | AH9: =IF($Z9="","",MATCH($AF9,WorkDays,1)-MATCH($Z9,WorkDays,1)) -> -77 | AI9: =IF($O9="","",$O9*IF($AB9<>"",1,$AC9)) | AJ9: Actual date as per P6.
A10: JSW USL-DE-CHI-1000 | B10: 3 | C10: Pile drawings release | J10: =SUMIF($B$11:$B$13,4,$J$11:$J$13) -> 0 | O10: =IF(SUMIF($B$11:$B$13,4,$O$11:$O$13)=0,"",SUMIF($B$11:$B$13,4,$O$11:$O$13)) | Y10: =MIN($Y$11:$Y$13) -> 46060 | Z10: =MAX($Z$11:$Z$13) -> 46083 | AA10: =IF(COUNT($AA$11:$AA$13)=0,"",MIN($AA$11:$AA$13)) -> 45990 | AB10: =IF(COUNTIFS($B$11:$B$13,4,$AG$11:$AG$13,"Completed")=COUNTIF($B$11:$B$13,4),MAX($AB$11:$AB$13),"") -> 46013 | AC10: =IFERROR(IF(SUMIF($B$11:$B$13,4,$O$11:$O$13)>0,SUMIF($B$11:$B$13,4,$AI$11:$AI$13)/SUMIF($B$11:$B$13,4,$O$11:$O$13),IFERROR(SUMPRODUCT(--($B$11:$B$13=4),$Q$11:$Q$13,$AC$11:$AC$13)/SUMIF($B$11:$B$13,4,$Q$11:$Q$13),AVERAGEIF($B$11:$B$13,4,$AC$11:$AC$13))),"") -> 1 | AE10: =MIN($AE$11:$AE$13) -> 45990 | AF10: =MAX($AF$11:$AF$13) -> 46013 | AG10: =IF(COUNTIFS($B$11:$B$13,4,$AG$11:$AG$13,"Completed")=COUNTIF($B$11:$B$13,4),"Completed",IF(COUNTIFS($B$11:$B$13,4,$AG$11:$AG$13,"Not Started*")=COUNTIF($B$11:$B$13,4),"Not Started","In Progress")) -> Completed | AH10: =MATCH($AF10,WorkDays,1)-MATCH($Z10,WorkDays,1) -> -57 | AI10: =IF(SUMIF($B$11:$B$13,4,$O$11:$O$13)=0,"",SUMIF($B$11:$B$13,4,$AI$11:$AI$13)) | AJ10: ="P6 check: "&INDEX('P6 Roll-up'!$AB$5:$AB$22,MATCH($A10,'P6 Roll-up'!$A$5:$A$22,0)) -> P6 check: ✔ Same as P6
A11: CHP-ENG-010 | B11: 4 | C11: Pile layout & detail drawing (19530-001) – design & preparation | D11: Engineering | H11: — (non-BIM) | J11: =COUNTIF('BIM Element Map'!$J$6:$J$1000,$A11) -> 0 | L11: Construct | M11: O24091-990-C-B-19530-001 | N11: JSW USL-DE-CHI-1000 | Q11: 14 | X11: 45990 | Y11: 46060 | Z11: 46076 | AA11: 45990 | AB11: 46006 | AC11: 1 | AD11: =IF($AB11<>"",0,IF($AA11="",$Q11,MAX(1,ROUND($Q11*(1-$AC11),0)))) -> 0 | AE11: =IF($AA11<>"",$AA11,MAX($X11,NextWD,IF($R11="",0,IF($S11="SS",INDEX(WorkDays,MATCH(INDEX($AE$6:$AE$156,MATCH($R11,$A$6:$A$156,0))-1,WorkDays,1)+1+$T11),INDEX(WorkDays,MATCH(INDEX($AF$6:$AF$156,MATCH($R11,$A$6:$A$156,0)),WorkDays,1)+IF($Q11=0,0,1)+$T11))),IF($U11="",0,IF($V11="SS",INDEX(WorkDays,MATCH(INDEX($AE$6:$AE$156,MATCH($U11,$A$6:$A$156,0))-1,WorkDays,1)+1+$W11),INDEX(WorkDays,MATCH(INDEX($AF$6:$AF$156,MATCH($U11,$A$6:$A$156,0)),WorkDays,1)+IF($Q11=0,0,1)+$W11))))) -> 45990 | AF11: =IF($AB11<>"",$AB11,IF($Q11=0,$AE11,INDEX(WorkDays,MATCH(MAX($AE11,NextWD)-1,WorkDays,1)+$AD11))) -> 46006 | AG11: =IF($AB11<>"","Completed",IF($AA11<>"","In Progress",IF(AND($Y11<>"",$Y11<=DataDate),"Not Started (Late)","Not Started"))) -> Completed | AH11: =IF($Z11="","",MATCH($AF11,WorkDays,1)-MATCH($Z11,WorkDays,1)) -> -57 | AI11: =IF($O11="","",$O11*IF($AB11<>"",1,$AC11)) | AJ11: Group actual dates = P6; split inside the group ASSUMED (sequenced) – replace with register / DPR dates.
A12: CHP-ENG-020 | B12: 4 | C12: Pile drawing – review, client approval & IFC issue | D12: Engineering | H12: — (non-BIM) | J12: =COUNTIF('BIM Element Map'!$J$6:$J$1000,$A12) -> 0 | L12: Construct | M12: O24091-990-C-B-19530-001 | N12: JSW USL-DE-CHI-1000 | Q12: 6 | R12: CHP-ENG-010 | S12: FS | T12: 0 | Y12: 46077 | Z12: 46083 | AA12: 46007 | AB12: 46013 | AC12: 1 | AD12: =IF($AB12<>"",0,IF($AA12="",$Q12,MAX(1,ROUND($Q12*(1-$AC12),0)))) -> 0 | AE12: =IF($AA12<>"",$AA12,MAX($X12,NextWD,IF($R12="",0,IF($S12="SS",INDEX(WorkDays,MATCH(INDEX($AE$6:$AE$156,MATCH($R12,$A$6:$A$156,0))-1,WorkDays,1)+1+$T12),INDEX(WorkDays,MATCH(INDEX($AF$6:$AF$156,MATCH($R12,$A$6:$A$156,0)),WorkDays,1)+IF($Q12=0,0,1)+$T12))),IF($U12="",0,IF($V12="SS",INDEX(WorkDays,MATCH(INDEX($AE$6:$AE$156,MATCH($U12,$A$6:$A$156,0))-1,WorkDays,1)+1+$W12),INDEX(WorkDays,MATCH(INDEX($AF$6:$AF$156,MATCH($U12,$A$6:$A$156,0)),WorkDays,1)+IF($Q12=0,0,1)+$W12))))) -> 46007 | AF12: =IF($AB12<>"",$AB12,IF($Q12=0,$AE12,INDEX(WorkDays,MATCH(MAX($AE12,NextWD)-1,WorkDays,1)+$AD12))) -> 46013 | AG12: =IF($AB12<>"","Completed",IF($AA12<>"","In Progress",IF(AND($Y12<>"",$Y12<=DataDate),"Not Started (Late)","Not Started"))) -> Completed | AH12: =IF($Z12="","",MATCH($AF12,WorkDays,1)-MATCH($Z12,WorkDays,1)) -> -57 | AI12: =IF($O12="","",$O12*IF($AB12<>"",1,$AC12)) | AJ12: Group actual dates = P6; split inside the group ASSUMED (sequenced) – replace with register / DPR dates.
A13: CHP-MS-020 | B13: 4 | C13: Pile drawings released (IFC) | D13: Milestone | H13: — (non-BIM milestone) | J13: =COUNTIF('BIM Element Map'!$J$6:$J$1000,$A13) -> 0 | L13: Milestone | M13: O24091-990-C-B-19530-001 | N13: JSW USL-DE-CHI-1000 | Q13: 0 | R13: CHP-ENG-020 | S13: FS | T13: 0 | Y13: 46083 | Z13: 46083 | AA13: 46013 | AB13: 46013 | AC13: 1 | AD13: =IF($AB13<>"",0,IF($AA13="",$Q13,MAX(1,ROUND($Q13*(1-$AC13),0)))) -> 0 | AE13: =IF($AA13<>"",$AA13,MAX($X13,NextWD,IF($R13="",0,IF($S13="SS",INDEX(WorkDays,MATCH(INDEX($AE$6:$AE$156,MATCH($R13,$A$6:$A$156,0))-1,WorkDays,1)+1+$T13),INDEX(WorkDays,MATCH(INDEX($AF$6:$AF$156,MATCH($R13,$A$6:$A$156,0)),WorkDays,1)+IF($Q13=0,0,1)+$T13))),IF($U13="",0,IF($V13="SS",INDEX(WorkDays,MATCH(INDEX($AE$6:$AE$156,MATCH($U13,$A$6:$A$156,0))-1,WorkDays,1)+1+$W13),INDEX(WorkDays,MATCH(INDEX($AF$6:$AF$156,MATCH($U13,$A$6:$A$156,0)),WorkDays,1)+IF($Q13=0,0,1)+$W13))))) -> 46013 | AF13: =IF($AB13<>"",$AB13,IF($Q13=0,$AE13,INDEX(WorkDays,MATCH(MAX($AE13,NextWD)-1,WorkDays,1)+$AD13))) -> 46013 | AG13: =IF($AB13<>"","Completed",IF($AA13<>"","In Progress",IF(AND($Y13<>"",$Y13<=DataDate),"Not Started (Late)","Not Started"))) -> Completed | AH13: =IF($Z13="","",MATCH($AF13,WorkDays,1)-MATCH($Z13,WorkDays,1)) -> -57 | AI13: =IF($O13="","",$O13*IF($AB13<>"",1,$AC13)) | AJ13: Group actual dates = P6; split inside the group ASSUMED (sequenced) – replace with register / DPR dates.
A14: JSW USL-DE-CHI-1010 | B14: 3 | C14: Civil drawings release | J14: =SUMIF($B$15:$B$17,4,$J$15:$J$17) -> 0 | O14: =IF(SUMIF($B$15:$B$17,4,$O$15:$O$17)=0,"",SUMIF($B$15:$B$17,4,$O$15:$O$17)) | Y14: =MIN($Y$15:$Y$17) -> 46042 | Z14: =MAX($Z$15:$Z$17) -> 46077 | AA14: =IF(COUNT($AA$15:$AA$17)=0,"",MIN($AA$15:$AA$17)) -> 46014 | AB14: =IF(COUNTIFS($B$15:$B$17,4,$AG$15:$AG$17,"Completed")=COUNTIF($B$15:$B$17,4),MAX($AB$15:$AB$17),"") -> 46029 | AC14: =IFERROR(IF(SUMIF($B$15:$B$17,4,$O$15:$O$17)>0,SUMIF($B$15:$B$17,4,$AI$15:$AI$17)/SUMIF($B$15:$B$17,4,$O$15:$O$17),IFERROR(SUMPRODUCT(--($B$15:$B$17=4),$Q$15:$Q$17,$AC$15:$AC$17)/SUMIF($B$15:$B$17,4,$Q$15:$Q$17),AVERAGEIF($B$15:$B$17,4,$AC$15:$AC$17))),"") -> 1 | AE14: =MIN($AE$15:$AE$17) -> 46014 | AF14: =MAX($AF$15:$AF$17) -> 46029 | AG14: =IF(COUNTIFS($B$15:$B$17,4,$AG$15:$AG$17,"Completed")=COUNTIF($B$15:$B$17,4),"Completed",IF(COUNTIFS($B$15:$B$17,4,$AG$15:$AG$17,"Not Started*")=COUNTIF($B$15:$B$17,4),"Not Started","In Progress")) -> Completed | AH14: =MATCH($AF14,WorkDays,1)-MATCH($Z14,WorkDays,1) -> -40 | AI14: =IF(SUMIF($B$15:$B$17,4,$O$15:$O$17)=0,"",SUMIF($B$15:$B$17,4,$AI$15:$AI$17)) | AJ14: ="P6 check: "&INDEX('P6 Roll-up'!$AB$5:$AB$22,MATCH($A14,'P6 Roll-up'!$A$5:$A$22,0)) -> P6 check: ✔ Same as P6
A15: CHP-ENG-030 | B15: 4 | C15: Civil GA & RC drawings 19531-001 … 008 – preparation & checking | D15: Engineering | H15: — (non-BIM) | J15: =COUNTIF('BIM Element Map'!$J$6:$J$1000,$A15) -> 0 | L15: Construct | M15: O24091-990-C-B-19531-001 … 008 | N15: JSW USL-DE-CHI-1010 | Q15: 7 | X15: 46014 | Y15: 46042 | Z15: 46063 | AA15: 46014 | AB15: 46022 | AC15: 1 | AD15: =IF($AB15<>"",0,IF($AA15="",$Q15,MAX(1,ROUND($Q15*(1-$AC15),0)))) -> 0 | AE15: =IF($AA15<>"",$AA15,MAX($X15,NextWD,IF($R15="",0,IF($S15="SS",INDEX(WorkDays,MATCH(INDEX($AE$6:$AE$156,MATCH($R15,$A$6:$A$156,0))-1,WorkDays,1)+1+$T15),INDEX(WorkDays,MATCH(INDEX($AF$6:$AF$156,MATCH($R15,$A$6:$A$156,0)),WorkDays,1)+IF($Q15=0,0,1)+$T15))),IF($U15="",0,IF($V15="SS",INDEX(WorkDays,MATCH(INDEX($AE$6:$AE$156,MATCH($U15,$A$6:$A$156,0))-1,WorkDays,1)+1+$W15),INDEX(WorkDays,MATCH(INDEX($AF$6:$AF$156,MATCH($U15,$A$6:$A$156,0)),WorkDays,1)+IF($Q15=0,0,1)+$W15))))) -> 46014 | AF15: =IF($AB15<>"",$AB15,IF($Q15=0,$AE15,INDEX(WorkDays,MATCH(MAX($AE15,NextWD)-1,WorkDays,1)+$AD15))) -> 46022 | AG15: =IF($AB15<>"","Completed",IF($AA15<>"","In Progress",IF(AND($Y15<>"",$Y15<=DataDate),"Not Started (Late)","Not Started"))) -> Completed | AH15: =IF($Z15="","",MATCH($AF15,WorkDays,1)-MATCH($Z15,WorkDays,1)) -> -33 | AI15: =IF($O15="","",$O15*IF($AB15<>"",1,$AC15)) | AJ15: Group actual dates = P6; split inside the group ASSUMED (sequenced) – replace with register / DPR dates.
A16: CHP-ENG-040 | B16: 4 | C16: Civil drawings – client review & IFC release | D16: Engineering | H16: — (non-BIM) | J16: =COUNTIF('BIM Element Map'!$J$6:$J$1000,$A16) -> 0 | L16: Construct | M16: O24091-990-C-B-19531-001 … 008 | N16: JSW USL-DE-CHI-1010 | Q16: 5 | R16: CHP-ENG-030 | S16: FS | T16: 0 | Y16: 46064 | Z16: 46077 | AA16: 46024 | AB16: 46029 | AC16: 1 | AD16: =IF($AB16<>"",0,IF($AA16="",$Q16,MAX(1,ROUND($Q16*(1-$AC16),0)))) -> 0 | AE16: =IF($AA16<>"",$AA16,MAX($X16,NextWD,IF($R16="",0,IF($S16="SS",INDEX(WorkDays,MATCH(INDEX($AE$6:$AE$156,MATCH($R16,$A$6:$A$156,0))-1,WorkDays,1)+1+$T16),INDEX(WorkDays,MATCH(INDEX($AF$6:$AF$156,MATCH($R16,$A$6:$A$156,0)),WorkDays,1)+IF($Q16=0,0,1)+$T16))),IF($U16="",0,IF($V16="SS",INDEX(WorkDays,MATCH(INDEX($AE$6:$AE$156,MATCH($U16,$A$6:$A$156,0))-1,WorkDays,1)+1+$W16),INDEX(WorkDays,MATCH(INDEX($AF$6:$AF$156,MATCH($U16,$A$6:$A$156,0)),WorkDays,1)+IF($Q16=0,0,1)+$W16))))) -> 46024 | AF16: =IF($AB16<>"",$AB16,IF($Q16=0,$AE16,INDEX(WorkDays,MATCH(MAX($AE16,NextWD)-1,WorkDays,1)+$AD16))) -> 46029 | AG16: =IF($AB16<>"","Completed",IF($AA16<>"","In Progress",IF(AND($Y16<>"",$Y16<=DataDate),"Not Started (Late)","Not Started"))) -> Completed | AH16: =IF($Z16="","",MATCH($AF16,WorkDays,1)-MATCH($Z16,WorkDays,1)) -> -40 | AI16: =IF($O16="","",$O16*IF($AB16<>"",1,$AC16)) | AJ16: Group actual dates = P6; split inside the group ASSUMED (sequenced) – replace with register / DPR dates.
A17: CHP-MS-030 | B17: 4 | C17: Civil drawings released (IFC) | D17: Milestone | H17: — (non-BIM milestone) | J17: =COUNTIF('BIM Element Map'!$J$6:$J$1000,$A17) -> 0 | L17: Milestone | N17: JSW USL-DE-CHI-1010 | Q17: 0 | R17: CHP-ENG-040 | S17: FS | T17: 0 | Y17: 46077 | Z17: 46077 | AA17: 46029 | AB17: 46029 | AC17: 1 | AD17: =IF($AB17<>"",0,IF($AA17="",$Q17,MAX(1,ROUND($Q17*(1-$AC17),0)))) -> 0 | AE17: =IF($AA17<>"",$AA17,MAX($X17,NextWD,IF($R17="",0,IF($S17="SS",INDEX(WorkDays,MATCH(INDEX($AE$6:$AE$156,MATCH($R17,$A$6:$A$156,0))-1,WorkDays,1)+1+$T17),INDEX(WorkDays,MATCH(INDEX($AF$6:$AF$156,MATCH($R17,$A$6:$A$156,0)),WorkDays,1)+IF($Q17=0,0,1)+$T17))),IF($U17="",0,IF($V17="SS",INDEX(WorkDays,MATCH(INDEX($AE$6:$AE$156,MATCH($U17,$A$6:$A$156,0))-1,WorkDays,1)+1+$W17),INDEX(WorkDays,MATCH(INDEX($AF$6:$AF$156,MATCH($U17,$A$6:$A$156,0)),WorkDays,1)+IF($Q17=0,0,1)+$W17))))) -> 46029 | AF17: =IF($AB17<>"",$AB17,IF($Q17=0,$AE17,INDEX(WorkDays,MATCH(MAX($AE17,NextWD)-1,WorkDays,1)+$AD17))) -> 46029 | AG17: =IF($AB17<>"","Completed",IF($AA17<>"","In Progress",IF(AND($Y17<>"",$Y17<=DataDate),"Not Started (Late)","Not Started"))) -> Completed | AH17: =IF($Z17="","",MATCH($AF17,WorkDays,1)-MATCH($Z17,WorkDays,1)) -> -40 | AI17: =IF($O17="","",$O17*IF($AB17<>"",1,$AC17)) | AJ17: Group actual dates = P6; split inside the group ASSUMED (sequenced) – replace with register / DPR dates.
A18: JSW USL-DE-CHI-1020 | B18: 3 | C18: Equipment drawings release | J18: =SUMIF($B$19:$B$21,4,$J$19:$J$21) -> 0 | O18: =IF(SUMIF($B$19:$B$21,4,$O$19:$O$21)=0,"",SUMIF($B$19:$B$21,4,$O$19:$O$21)) | Y18: =MIN($Y$19:$Y$21) -> 46265 | Z18: =MAX($Z$19:$Z$21) -> 46305 | AA18: =IF(COUNT($AA$19:$AA$21)=0,"",MIN($AA$19:$AA$21)) -> 46265 | AB18: =IF(COUNTIFS($B$19:$B$21,4,$AG$19:$AG$21,"Completed")=COUNTIF($B$19:$B$21,4),MAX($AB$19:$AB$21),"") -> 46289 | AC18: =IFERROR(IF(SUMIF($B$19:$B$21,4,$O$19:$O$21)>0,SUMIF($B$19:$B$21,4,$AI$19:$AI$21)/SUMIF($B$19:$B$21,4,$O$19:$O$21),IFERROR(SUMPRODUCT(--($B$19:$B$21=4),$Q$19:$Q$21,$AC$19:$AC$21)/SUMIF($B$19:$B$21,4,$Q$19:$Q$21),AVERAGEIF($B$19:$B$21,4,$AC$19:$AC$21))),"") -> 1 | AE18: =MIN($AE$19:$AE$21) -> 46265 | AF18: =MAX($AF$19:$AF$21) -> 46289 | AG18: =IF(COUNTIFS($B$19:$B$21,4,$AG$19:$AG$21,"Completed")=COUNTIF($B$19:$B$21,4),"Completed",IF(COUNTIFS($B$19:$B$21,4,$AG$19:$AG$21,"Not Started*")=COUNTIF($B$19:$B$21,4),"Not Started","In Progress")) -> Completed | AH18: =MATCH($AF18,WorkDays,1)-MATCH($Z18,WorkDays,1) -> -13 | AI18: =IF(SUMIF($B$19:$B$21,4,$O$19:$O$21)=0,"",SUMIF($B$19:$B$21,4,$AI$19:$AI$21)) | AJ18: ="P6 check: "&INDEX('P6 Roll-up'!$AB$5:$AB$22,MATCH($A18,'P6 Roll-up'!$A$5:$A$22,0)) -> P6 check: ✔ Same as P6
A19: CHP-ENG-050 | B19: 4 | C19: Vendor GA drawings (centrifugal chillers & pumps) – receipt & review | D19: Engineering | H19: — (non-BIM) | J19: =COUNTIF('BIM Element Map'!$J$6:$J$1000,$A19) -> 0 | L19: Construct | N19: JSW USL-DE-CHI-1020 | Q19: 13 | X19: 46265 | Y19: 46265 | Z19: 46288 | AA19: 46265 | AB19: 46279 | AC19: 1 | AD19: =IF($AB19<>"",0,IF($AA19="",$Q19,MAX(1,ROUND($Q19*(1-$AC19),0)))) -> 0 | AE19: =IF($AA19<>"",$AA19,MAX($X19,NextWD,IF($R19="",0,IF($S19="SS",INDEX(WorkDays,MATCH(INDEX($AE$6:$AE$156,MATCH($R19,$A$6:$A$156,0))-1,WorkDays,1)+1+$T19),INDEX(WorkDays,MATCH(INDEX($AF$6:$AF$156,MATCH($R19,$A$6:$A$156,0)),WorkDays,1)+IF($Q19=0,0,1)+$T19))),IF($U19="",0,IF($V19="SS",INDEX(WorkDays,MATCH(INDEX($AE$6:$AE$156,MATCH($U19,$A$6:$A$156,0))-1,WorkDays,1)+1+$W19),INDEX(WorkDays,MATCH(INDEX($AF$6:$AF$156,MATCH($U19,$A$6:$A$156,0)),WorkDays,1)+IF($Q19=0,0,1)+$W19))))) -> 46265 | AF19: =IF($AB19<>"",$AB19,IF($Q19=0,$AE19,INDEX(WorkDays,MATCH(MAX($AE19,NextWD)-1,WorkDays,1)+$AD19))) -> 46279 | AG19: =IF($AB19<>"","Completed",IF($AA19<>"","In Progress",IF(AND($Y19<>"",$Y19<=DataDate),"Not Started (Late)","Not Started"))) -> Completed | AH19: =IF($Z19="","",MATCH($AF19,WorkDays,1)-MATCH($Z19,WorkDays,1)) -> -8 | AI19: =IF($O19="","",$O19*IF($AB19<>"",1,$AC19)) | AJ19: Group actual dates = P6; split inside the group ASSUMED (sequenced) – replace with register / DPR dates.
A20: CHP-ENG-060 | B20: 4 | C20: Equipment layout & foundation loading data – approval & release | D20: Engineering | H20: — (non-BIM) | J20: =COUNTIF('BIM Element Map'!$J$6:$J$1000,$A20) -> 0 | L20: Construct | N20: JSW USL-DE-CHI-1020 | Q20: 9 | R20: CHP-ENG-050 | S20: FS | T20: 0 | Y20: 46289 | Z20: 46305 | AA20: 46280 | AB20: 46289 | AC20: 1 | AD20: =IF($AB20<>"",0,IF($AA20="",$Q20,MAX(1,ROUND($Q20*(1-$AC20),0)))) -> 0 | AE20: =IF($AA20<>"",$AA20,MAX($X20,NextWD,IF($R20="",0,IF($S20="SS",INDEX(WorkDays,MATCH(INDEX($AE$6:$AE$156,MATCH($R20,$A$6:$A$156,0))-1,WorkDays,1)+1+$T20),INDEX(WorkDays,MATCH(INDEX($AF$6:$AF$156,MATCH($R20,$A$6:$A$156,0)),WorkDays,1)+IF($Q20=0,0,1)+$T20))),IF($U20="",0,IF($V20="SS",INDEX(WorkDays,MATCH(INDEX($AE$6:$AE$156,MATCH($U20,$A$6:$A$156,0))-1,WorkDays,1)+1+$W20),INDEX(WorkDays,MATCH(INDEX($AF$6:$AF$156,MATCH($U20,$A$6:$A$156,0)),WorkDays,1)+IF($Q20=0,0,1)+$W20))))) -> 46280 | AF20: =IF($AB20<>"",$AB20,IF($Q20=0,$AE20,INDEX(WorkDays,MATCH(MAX($AE20,NextWD)-1,WorkDays,1)+$AD20))) -> 46289 | AG20: =IF($AB20<>"","Completed",IF($AA20<>"","In Progress",IF(AND($Y20<>"",$Y20<=DataDate),"Not Started (Late)","Not Started"))) -> Completed | AH20: =IF($Z20="","",MATCH($AF20,WorkDays,1)-MATCH($Z20,WorkDays,1)) -> -13 | AI20: =IF($O20="","",$O20*IF($AB20<>"",1,$AC20)) | AJ20: Group actual dates = P6; split inside the group ASSUMED (sequenced) – replace with register / DPR dates.
A21: CHP-MS-040 | B21: 4 | C21: Equipment drawings released – HOLD on chiller / pump foundations F1 & F2 lifted | D21: Milestone | H21: — (non-BIM milestone) | J21: =COUNTIF('BIM Element Map'!$J$6:$J$1000,$A21) -> 0 | L21: Milestone | M21: O24091-990-C-B-19531-007 | N21: JSW USL-DE-CHI-1020 | Q21: 0 | R21: CHP-ENG-060 | S21: FS | T21: 0 | Y21: 46305 | Z21: 46305 | AA21: 46289 | AB21: 46289 | AC21: 1 | AD21: =IF($AB21<>"",0,IF($AA21="",$Q21,MAX(1,ROUND($Q21*(1-$AC21),0)))) -> 0 | AE21: =IF($AA21<>"",$AA21,MAX($X21,NextWD,IF($R21="",0,IF($S21="SS",INDEX(WorkDays,MATCH(INDEX($AE$6:$AE$156,MATCH($R21,$A$6:$A$156,0))-1,WorkDays,1)+1+$T21),INDEX(WorkDays,MATCH(INDEX($AF$6:$AF$156,MATCH($R21,$A$6:$A$156,0)),WorkDays,1)+IF($Q21=0,0,1)+$T21))),IF($U21="",0,IF($V21="SS",INDEX(WorkDays,MATCH(INDEX($AE$6:$AE$156,MATCH($U21,$A$6:$A$156,0))-1,WorkDays,1)+1+$W21),INDEX(WorkDays,MATCH(INDEX($AF$6:$AF$156,MATCH($U21,$A$6:$A$156,0)),WorkDays,1)+IF($Q21=0,0,1)+$W21))))) -> 46289 | AF21: =IF($AB21<>"",$AB21,IF($Q21=0,$AE21,INDEX(WorkDays,MATCH(MAX($AE21,NextWD)-1,WorkDays,1)+$AD21))) -> 46289 | AG21: =IF($AB21<>"","Completed",IF($AA21<>"","In Progress",IF(AND($Y21<>"",$Y21<=DataDate),"Not Started (Late)","Not Started"))) -> Completed | AH21: =IF($Z21="","",MATCH($AF21,WorkDays,1)-MATCH($Z21,WorkDays,1)) -> -13 | AI21: =IF($O21="","",$O21*IF($AB21<>"",1,$AC21)) | AJ21: Group actual dates = P6; split inside the group ASSUMED (sequenced) – replace with register / DPR dates.
A22: JSW USL-DE-CHI-1030 | B22: 3 | C22: Piping drawings release | J22: =SUMIF($B$23:$B$25,4,$J$23:$J$25) -> 0 | O22: =IF(SUMIF($B$23:$B$25,4,$O$23:$O$25)=0,"",SUMIF($B$23:$B$25,4,$O$23:$O$25)) | Y22: =MIN($Y$23:$Y$25) -> 46307 | Z22: =MAX($Z$23:$Z$25) -> 46359 | AA22: =IF(COUNT($AA$23:$AA$25)=0,"",MIN($AA$23:$AA$25)) | AB22: =IF(COUNTIFS($B$23:$B$25,4,$AG$23:$AG$25,"Completed")=COUNTIF($B$23:$B$25,4),MAX($AB$23:$AB$25),"") | AC22: =IFERROR(IF(SUMIF($B$23:$B$25,4,$O$23:$O$25)>0,SUMIF($B$23:$B$25,4,$AI$23:$AI$25)/SUMIF($B$23:$B$25,4,$O$23:$O$25),IFERROR(SUMPRODUCT(--($B$23:$B$25=4),$Q$23:$Q$25,$AC$23:$AC$25)/SUMIF($B$23:$B$25,4,$Q$23:$Q$25),AVERAGEIF($B$23:$B$25,4,$AC$23:$AC$25))),"") -> 0 | AE22: =MIN($AE$23:$AE$25) -> 46298 | AF22: =MAX($AF$23:$AF$25) -> 46345 | AG22: =IF(COUNTIFS($B$23:$B$25,4,$AG$23:$AG$25,"Completed")=COUNTIF($B$23:$B$25,4),"Completed",IF(COUNTIFS($B$23:$B$25,4,$AG$23:$AG$25,"Not Started*")=COUNTIF($B$23:$B$25,4),"Not Started","In Progress")) -> Not Started | AH22: =MATCH($AF22,WorkDays,1)-MATCH($Z22,WorkDays,1) -> -12 | AI22: =IF(SUMIF($B$23:$B$25,4,$O$23:$O$25)=0,"",SUMIF($B$23:$B$25,4,$AI$23:$AI$25)) | AJ22: ="P6 check: "&INDEX('P6 Roll-up'!$AB$5:$AB$22,MATCH($A22,'P6 Roll-up'!$A$5:$A$22,0)) -> P6 check: ✔ Same as P6
A23: CHP-ENG-070 | B23: 4 | C23: Piping GA, isometric & pipe-support drawings – preparation | D23: Engineering | H23: — (non-BIM) | J23: =COUNTIF('BIM Element Map'!$J$6:$J$1000,$A23) -> 0 | L23: Construct | N23: JSW USL-DE-CHI-1030 | Q23: 30 | X23: 46298 | Y23: 46307 | Z23: 46346 | AC23: 0 | AD23: =IF($AB23<>"",0,IF($AA23="",$Q23,MAX(1,ROUND($Q23*(1-$AC23),0)))) -> 30 | AE23: =IF($AA23<>"",$AA23,MAX($X23,NextWD,IF($R23="",0,IF($S23="SS",INDEX(WorkDays,MATCH(INDEX($AE$6:$AE$156,MATCH($R23,$A$6:$A$156,0))-1,WorkDays,1)+1+$T23),INDEX(WorkDays,MATCH(INDEX($AF$6:$AF$156,MATCH($R23,$A$6:$A$156,0)),WorkDays,1)+IF($Q23=0,0,1)+$T23))),IF($U23="",0,IF($V23="SS",INDEX(WorkDays,MATCH(INDEX($AE$6:$AE$156,MATCH($U23,$A$6:$A$156,0))-1,WorkDays,1)+1+$W23),INDEX(WorkDays,MATCH(INDEX($AF$6:$AF$156,MATCH($U23,$A$6:$A$156,0)),WorkDays,1)+IF($Q23=0,0,1)+$W23))))) -> 46298 | AF23: =IF($AB23<>"",$AB23,IF($Q23=0,$AE23,INDEX(WorkDays,MATCH(MAX($AE23,NextWD)-1,WorkDays,1)+$AD23))) -> 46333 | AG23: =IF($AB23<>"","Completed",IF($AA23<>"","In Progress",IF(AND($Y23<>"",$Y23<=DataDate),"Not Started (Late)","Not Started"))) -> Not Started | AH23: =IF($Z23="","",MATCH($AF23,WorkDays,1)-MATCH($Z23,WorkDays,1)) -> -11 | AI23: =IF($O23="","",$O23*IF($AB23<>"",1,$AC23)) | AJ23: Sequenced to finish on P6 date 19-Nov-26.
A24: CHP-ENG-080 | B24: 4 | C24: Piping drawings – review, comments & IFC release | D24: Engineering | H24: — (non-BIM) | J24: =COUNTIF('BIM Element Map'!$J$6:$J$1000,$A24) -> 0 | L24: Construct | N24: JSW USL-DE-CHI-1030 | Q24: 10 | R24: CHP-ENG-070 | S24: FS | T24: 0 | Y24: 46347 | Z24: 46359 | AC24: 0 | AD24: =IF($AB24<>"",0,IF($AA24="",$Q24,MAX(1,ROUND($Q24*(1-$AC24),0)))) -> 10 | AE24: =IF($AA24<>"",$AA24,MAX($X24,NextWD,IF($R24="",0,IF($S24="SS",INDEX(WorkDays,MATCH(INDEX($AE$6:$AE$156,MATCH($R24,$A$6:$A$156,0))-1,WorkDays,1)+1+$T24),INDEX(WorkDays,MATCH(INDEX($AF$6:$AF$156,MATCH($R24,$A$6:$A$156,0)),WorkDays,1)+IF($Q24=0,0,1)+$T24))),IF($U24="",0,IF($V24="SS",INDEX(WorkDays,MATCH(INDEX($AE$6:$AE$156,MATCH($U24,$A$6:$A$156,0))-1,WorkDays,1)+1+$W24),INDEX(WorkDays,MATCH(INDEX($AF$6:$AF$156,MATCH($U24,$A$6:$A$156,0)),WorkDays,1)+IF($Q24=0,0,1)+$W24))))) -> 46335 | AF24: =IF($AB24<>"",$AB24,IF($Q24=0,$AE24,INDEX(WorkDays,MATCH(MAX($AE24,NextWD)-1,WorkDays,1)+$AD24))) -> 46345 | AG24: =IF($AB24<>"","Completed",IF($AA24<>"","In Progress",IF(AND($Y24<>"",$Y24<=DataDate),"Not Started (Late)","Not Started"))) -> Not Started | AH24: =IF($Z24="","",MATCH($AF24,WorkDays,1)-MATCH($Z24,WorkDays,1)) -> -12 | AI24: =IF($O24="","",$O24*IF($AB24<>"",1,$AC24)) | AJ24: Sequenced to finish on P6 date 19-Nov-26.
A25: CHP-MS-050 | B25: 4 | C25: Piping drawings released (IFC) | D25: Milestone | H25: — (non-BIM milestone) | J25: =COUNTIF('BIM Element Map'!$J$6:$J$1000,$A25) -> 0 | L25: Milestone | N25: JSW USL-DE-CHI-1030 | Q25: 0 | R25: CHP-ENG-080 | S25: FS | T25: 0 | Y25: 46359 | Z25: 46359 | AC25: 0 | AD25: =IF($AB25<>"",0,IF($AA25="",$Q25,MAX(1,ROUND($Q25*(1-$AC25),0)))) -> 0 | AE25: =IF($AA25<>"",$AA25,MAX($X25,NextWD,IF($R25="",0,IF($S25="SS",INDEX(WorkDays,MATCH(INDEX($AE$6:$AE$156,MATCH($R25,$A$6:$A$156,0))-1,WorkDays,1)+1+$T25),INDEX(WorkDays,MATCH(INDEX($AF$6:$AF$156,MATCH($R25,$A$6:$A$156,0)),WorkDays,1)+IF($Q25=0,0,1)+$T25))),IF($U25="",0,IF($V25="SS",INDEX(WorkDays,MATCH(INDEX($AE$6:$AE$156,MATCH($U25,$A$6:$A$156,0))-1,WorkDays,1)+1+$W25),INDEX(WorkDays,MATCH(INDEX($AF$6:$AF$156,MATCH($U25,$A$6:$A$156,0)),WorkDays,1)+IF($Q25=0,0,1)+$W25))))) -> 46345 | AF25: =IF($AB25<>"",$AB25,IF($Q25=0,$AE25,INDEX(WorkDays,MATCH(MAX($AE25,NextWD)-1,WorkDays,1)+$AD25))) -> 46345 | AG25: =IF($AB25<>"","Completed",IF($AA25<>"","In Progress",IF(AND($Y25<>"",$Y25<=DataDate),"Not Started (Late)","Not Started"))) -> Not Started | AH25: =IF($Z25="","",MATCH($AF25,WorkDays,1)-MATCH($Z25,WorkDays,1)) -> -12 | AI25: =IF($O25="","",$O25*IF($AB25<>"",1,$AC25)) | AJ25: Sequenced to finish on P6 date 19-Nov-26.
A26: JSW USL-DE-CHI-1040 | B26: 3 | C26: E&I drawings release | J26: =SUMIF($B$27:$B$29,4,$J$27:$J$29) -> 0 | O26: =IF(SUMIF($B$27:$B$29,4,$O$27:$O$29)=0,"",SUMIF($B$27:$B$29,4,$O$27:$O$29)) | Y26: =MIN($Y$27:$Y$29) -> 46360 | Z26: =MAX($Z$27:$Z$29) -> 46396 | AA26: =IF(COUNT($AA$27:$AA$29)=0,"",MIN($AA$27:$AA$29)) -> 46296 | AB26: =IF(COUNTIFS($B$27:$B$29,4,$AG$27:$AG$29,"Completed")=COUNTIF($B$27:$B$29,4),MAX($AB$27:$AB$29),"") | AC26: =IFERROR(IF(SUMIF($B$27:$B$29,4,$O$27:$O$29)>0,SUMIF($B$27:$B$29,4,$AI$27:$AI$29)/SUMIF($B$27:$B$29,4,$O$27:$O$29),IFERROR(SUMPRODUCT(--($B$27:$B$29=4),$Q$27:$Q$29,$AC$27:$AC$29)/SUMIF($B$27:$B$29,4,$Q$27:$Q$29),AVERAGEIF($B$27:$B$29,4,$AC$27:$AC$29))),"") -> 0.23265306 | AE26: =MIN($AE$27:$AE$29) -> 46296 | AF26: =MAX($AF$27:$AF$29) -> 46367 | AG26: =IF(COUNTIFS($B$27:$B$29,4,$AG$27:$AG$29,"Completed")=COUNTIF($B$27:$B$29,4),"Completed",IF(COUNTIFS($B$27:$B$29,4,$AG$27:$AG$29,"Not Started*")=COUNTIF($B$27:$B$29,4),"Not Started","In Progress")) -> In Progress | AH26: =MATCH($AF26,WorkDays,1)-MATCH($Z26,WorkDays,1) -> -23 | AI26: =IF(SUMIF($B$27:$B$29,4,$O$27:$O$29)=0,"",SUMIF($B$27:$B$29,4,$AI$27:$AI$29)) | AJ26: ="P6 check: "&INDEX('P6 Roll-up'!$AB$5:$AB$22,MATCH($A26,'P6 Roll-up'!$A$5:$A$22,0)) -> P6 check: ✔ Same as P6
A27: CHP-ENG-090 | B27: 4 | C27: E&I layouts (cable routing, lighting, earthing, instrument locations) – preparation | D27: Engineering | H27: — (non-BIM) | J27: =COUNTIF('BIM Element Map'!$J$6:$J$1000,$A27) -> 0 | L27: Construct | N27: JSW USL-DE-CHI-1040 | Q27: 30 | X27: 46296 | Y27: 46360 | Z27: 46371 | AA27: 46296 | AC27: 0.38 | AD27: =IF($AB27<>"",0,IF($AA27="",$Q27,MAX(1,ROUND($Q27*(1-$AC27),0)))) -> 19 | AE27: =IF($AA27<>"",$AA27,MAX($X27,NextWD,IF($R27="",0,IF($S27="SS",INDEX(WorkDays,MATCH(INDEX($AE$6:$AE$156,MATCH($R27,$A$6:$A$156,0))-1,WorkDays,1)+1+$T27),INDEX(WorkDays,MATCH(INDEX($AF$6:$AF$156,MATCH($R27,$A$6:$A$156,0)),WorkDays,1)+IF($Q27=0,0,1)+$T27))),IF($U27="",0,IF($V27="SS",INDEX(WorkDays,MATCH(INDEX($AE$6:$AE$156,MATCH($U27,$A$6:$A$156,0))-1,WorkDays,1)+1+$W27),INDEX(WorkDays,MATCH(INDEX($AF$6:$AF$156,MATCH($U27,$A$6:$A$156,0)),WorkDays,1)+IF($Q27=0,0,1)+$W27))))) -> 46296 | AF27: =IF($AB27<>"",$AB27,IF($Q27=0,$AE27,INDEX(WorkDays,MATCH(MAX($AE27,NextWD)-1,WorkDays,1)+$AD27))) -> 46321 | AG27: =IF($AB27<>"","Completed",IF($AA27<>"","In Progress",IF(AND($Y27<>"",$Y27<=DataDate),"Not Started (Late)","Not Started"))) -> In Progress | AH27: =IF($Z27="","",MATCH($AF27,WorkDays,1)-MATCH($Z27,WorkDays,1)) -> -43 | AI27: =IF($O27="","",$O27*IF($AB27<>"",1,$AC27)) | AJ27: Group actual dates = P6; split inside the group ASSUMED (sequenced) – replace with register / DPR dates. In progress at DD; remaining duration set so the group finishes on the P6 date.
A28: CHP-ENG-100 | B28: 4 | C28: E&I drawings – coordination with piping drawings, review & IFC release | D28: Engineering | H28: — (non-BIM) | J28: =COUNTIF('BIM Element Map'!$J$6:$J$1000,$A28) -> 0 | L28: Construct | N28: JSW USL-DE-CHI-1040 | Q28: 19 | R28: CHP-ENG-090 | S28: FS | T28: 0 | U28: CHP-MS-050 | V28: FS | W28: 0 | Y28: 46386 | Z28: 46396 | AC28: 0 | AD28: =IF($AB28<>"",0,IF($AA28="",$Q28,MAX(1,ROUND($Q28*(1-$AC28),0)))) -> 19 | AE28: =IF($AA28<>"",$AA28,MAX($X28,NextWD,IF($R28="",0,IF($S28="SS",INDEX(WorkDays,MATCH(INDEX($AE$6:$AE$156,MATCH($R28,$A$6:$A$156,0))-1,WorkDays,1)+1+$T28),INDEX(WorkDays,MATCH(INDEX($AF$6:$AF$156,MATCH($R28,$A$6:$A$156,0)),WorkDays,1)+IF($Q28=0,0,1)+$T28))),IF($U28="",0,IF($V28="SS",INDEX(WorkDays,MATCH(INDEX($AE$6:$AE$156,MATCH($U28,$A$6:$A$156,0))-1,WorkDays,1)+1+$W28),INDEX(WorkDays,MATCH(INDEX($AF$6:$AF$156,MATCH($U28,$A$6:$A$156,0)),WorkDays,1)+IF($Q28=0,0,1)+$W28))))) -> 46346 | AF28: =IF($AB28<>"",$AB28,IF($Q28=0,$AE28,INDEX(WorkDays,MATCH(MAX($AE28,NextWD)-1,WorkDays,1)+$AD28))) -> 46367 | AG28: =IF($AB28<>"","Completed",IF($AA28<>"","In Progress",IF(AND($Y28<>"",$Y28<=DataDate),"Not Started (Late)","Not Started"))) -> Not Started | AH28: =IF($Z28="","",MATCH($AF28,WorkDays,1)-MATCH($Z28,WorkDays,1)) -> -23 | AI28: =IF($O28="","",$O28*IF($AB28<>"",1,$AC28)) | AJ28: Sequenced to finish on P6 date 11-Dec-26.
A29: CHP-MS-060 | B29: 4 | C29: E&I drawings released (IFC) | D29: Milestone | H29: — (non-BIM milestone) | J29: =COUNTIF('BIM Element Map'!$J$6:$J$1000,$A29) -> 0 | L29: Milestone | N29: JSW USL-DE-CHI-1040 | Q29: 0 | R29: CHP-ENG-100 | S29: FS | T29: 0 | Y29: 46396 | Z29: 46396 | AC29: 0 | AD29: =IF($AB29<>"",0,IF($AA29="",$Q29,MAX(1,ROUND($Q29*(1-$AC29),0)))) -> 0 | AE29: =IF($AA29<>"",$AA29,MAX($X29,NextWD,IF($R29="",0,IF($S29="SS",INDEX(WorkDays,MATCH(INDEX($AE$6:$AE$156,MATCH($R29,$A$6:$A$156,0))-1,WorkDays,1)+1+$T29),INDEX(WorkDays,MATCH(INDEX($AF$6:$AF$156,MATCH($R29,$A$6:$A$156,0)),WorkDays,1)+IF($Q29=0,0,1)+$T29))),IF($U29="",0,IF($V29="SS",INDEX(WorkDays,MATCH(INDEX($AE$6:$AE$156,MATCH($U29,$A$6:$A$156,0))-1,WorkDays,1)+1+$W29),INDEX(WorkDays,MATCH(INDEX($AF$6:$AF$156,MATCH($U29,$A$6:$A$156,0)),WorkDays,1)+IF($Q29=0,0,1)+$W29))))) -> 46367 | AF29: =IF($AB29<>"",$AB29,IF($Q29=0,$AE29,INDEX(WorkDays,MATCH(MAX($AE29,NextWD)-1,WorkDays,1)+$AD29))) -> 46367 | AG29: =IF($AB29<>"","Completed",IF($AA29<>"","In Progress",IF(AND($Y29<>"",$Y29<=DataDate),"Not Started (Late)","Not Started"))) -> Not Started | AH29: =IF($Z29="","",MATCH($AF29,WorkDays,1)-MATCH($Z29,WorkDays,1)) -> -23 | AI29: =IF($O29="","",$O29*IF($AB29<>"",1,$AC29)) | AJ29: Sequenced to finish on P6 date 11-Dec-26.
A30: CHP.P | B30: 2 | C30: PROCUREMENT | J30: =SUMIF($B$31:$B$48,4,$J$31:$J$48) -> 0 | Y30: =MIN($Y$31:$Y$48) -> 46081 | Z30: =MAX($Z$31:$Z$48) -> 46380 | AA30: =IF(COUNT($AA$31:$AA$48)=0,"",MIN($AA$31:$AA$48)) -> 46056 | AB30: =IF(COUNTIFS($B$31:$B$48,4,$AG$31:$AG$48,"Completed")=COUNTIF($B$31:$B$48,4),MAX($AB$31:$AB$48),"") | AC30: =IFERROR(IFERROR(SUMPRODUCT(--($B$31:$B$48=4),$Q$31:$Q$48,$AC$31:$AC$48)/SUMIF($B$31:$B$48,4,$Q$31:$Q$48),AVERAGEIF($B$31:$B$48,4,$AC$31:$AC$48)),"") -> 0.72923339 | AE30: =MIN($AE$31:$AE$48) -> 46056 | AF30: =MAX($AF$31:$AF$48) -> 46387 | AG30: =IF(COUNTIFS($B$31:$B$48,4,$AG$31:$AG$48,"Completed")=COUNTIF($B$31:$B$48,4),"Completed",IF(COUNTIFS($B$31:$B$48,4,$AG$31:$AG$48,"Not Started*")=COUNTIF($B$31:$B$48,4),"Not Started","In Progress")) -> In Progress | AH30: =MATCH($AF30,WorkDays,1)-MATCH($Z30,WorkDays,1) -> 5
A31: JSW USL-PR-2440 | B31: 3 | C31: Centrifugal Chillers - PR to PO | J31: =SUMIF($B$32:$B$34,4,$J$32:$J$34) -> 0 | O31: =IF(SUMIF($B$32:$B$34,4,$O$32:$O$34)=0,"",SUMIF($B$32:$B$34,4,$O$32:$O$34)) | Y31: =MIN($Y$32:$Y$34) -> 46081 | Z31: =MAX($Z$32:$Z$34) -> 46154 | AA31: =IF(COUNT($AA$32:$AA$34)=0,"",MIN($AA$32:$AA$34)) -> 46056 | AB31: =IF(COUNTIFS($B$32:$B$34,4,$AG$32:$AG$34,"Completed")=COUNTIF($B$32:$B$34,4),MAX($AB$32:$AB$34),"") -> 46162 | AC31: =IFERROR(IF(SUMIF($B$32:$B$34,4,$O$32:$O$34)>0,SUMIF($B$32:$B$34,4,$AI$32:$AI$34)/SUMIF($B$32:$B$34,4,$O$32:$O$34),IFERROR(SUMPRODUCT(--($B$32:$B$34=4),$Q$32:$Q$34,$AC$32:$AC$34)/SUMIF($B$32:$B$34,4,$Q$32:$Q$34),AVERAGEIF($B$32:$B$34,4,$AC$32:$AC$34))),"") -> 1 | AE31: =MIN($AE$32:$AE$34) -> 46056 | AF31: =MAX($AF$32:$AF$34) -> 46162 | AG31: =IF(COUNTIFS($B$32:$B$34,4,$AG$32:$AG$34,"Completed")=COUNTIF($B$32:$B$34,4),"Completed",IF(COUNTIFS($B$32:$B$34,4,$AG$32:$AG$34,"Not Started*")=COUNTIF($B$32:$B$34,4),"Not Started","In Progress")) -> Completed | AH31: =MATCH($AF31,WorkDays,1)-MATCH($Z31,WorkDays,1) -> 7 | AI31: =IF(SUMIF($B$32:$B$34,4,$O$32:$O$34)=0,"",SUMIF($B$32:$B$34,4,$AI$32:$AI$34)) | AJ31: ="P6 check: "&INDEX('P6 Roll-up'!$AB$5:$AB$22,MATCH($A31,'P6 Roll-up'!$A$5:$A$22,0)) -> P6 check: ✔ Same as P6
A32: CHP-PRC-010 | B32: 4 | C32: Centrifugal chillers – PR, RFQ, bids & technical evaluation | D32: Procurement | H32: — (non-BIM) | J32: =COUNTIF('BIM Element Map'!$J$6:$J$1000,$A32) -> 0 | L32: Construct | N32: JSW USL-PR-2440 | Q32: 58 | X32: 46056 | Y32: 46081 | Z32: 46128 | AA32: 46056 | AB32: 46125 | AC32: 1 | AD32: =IF($AB32<>"",0,IF($AA32="",$Q32,MAX(1,ROUND($Q32*(1-$AC32),0)))) -> 0 | AE32: =IF($AA32<>"",$AA32,MAX($X32,NextWD,IF($R32="",0,IF($S32="SS",INDEX(WorkDays,MATCH(INDEX($AE$6:$AE$156,MATCH($R32,$A$6:$A$156,0))-1,WorkDays,1)+1+$T32),INDEX(WorkDays,MATCH(INDEX($AF$6:$AF$156,MATCH($R32,$A$6:$A$156,0)),WorkDays,1)+IF($Q32=0,0,1)+$T32))),IF($U32="",0,IF($V32="SS",INDEX(WorkDays,MATCH(INDEX($AE$6:$AE$156,MATCH($U32,$A$6:$A$156,0))-1,WorkDays,1)+1+$W32),INDEX(WorkDays,MATCH(INDEX($AF$6:$AF$156,MATCH($U32,$A$6:$A$156,0)),WorkDays,1)+IF($Q32=0,0,1)+$W32))))) -> 46056 | AF32: =IF($AB32<>"",$AB32,IF($Q32=0,$AE32,INDEX(WorkDays,MATCH(MAX($AE32,NextWD)-1,WorkDays,1)+$AD32))) -> 46125 | AG32: =IF($AB32<>"","Completed",IF($AA32<>"","In Progress",IF(AND($Y32<>"",$Y32<=DataDate),"Not Started (Late)","Not Started"))) -> Completed | AH32: =IF($Z32="","",MATCH($AF32,WorkDays,1)-MATCH($Z32,WorkDays,1)) -> -3 | AI32: =IF($O32="","",$O32*IF($AB32<>"",1,$AC32)) | AJ32: Group actual dates = P6; split inside the group ASSUMED (sequenced) – replace with register / DPR dates.
A33: CHP-PRC-020 | B33: 4 | C33: Centrifugal chillers – commercial negotiation & PO placement | D33: Procurement | H33: — (non-BIM) | J33: =COUNTIF('BIM Element Map'!$J$6:$J$1000,$A33) -> 0 | L33: Construct | N33: JSW USL-PR-2440 | Q33: 31 | R33: CHP-PRC-010 | S33: FS | T33: 0 | Y33: 46129 | Z33: 46154 | AA33: 46126 | AB33: 46162 | AC33: 1 | AD33: =IF($AB33<>"",0,IF($AA33="",$Q33,MAX(1,ROUND($Q33*(1-$AC33),0)))) -> 0 | AE33: =IF($AA33<>"",$AA33,MAX($X33,NextWD,IF($R33="",0,IF($S33="SS",INDEX(WorkDays,MATCH(INDEX($AE$6:$AE$156,MATCH($R33,$A$6:$A$156,0))-1,WorkDays,1)+1+$T33),INDEX(WorkDays,MATCH(INDEX($AF$6:$AF$156,MATCH($R33,$A$6:$A$156,0)),WorkDays,1)+IF($Q33=0,0,1)+$T33))),IF($U33="",0,IF($V33="SS",INDEX(WorkDays,MATCH(INDEX($AE$6:$AE$156,MATCH($U33,$A$6:$A$156,0))-1,WorkDays,1)+1+$W33),INDEX(WorkDays,MATCH(INDEX($AF$6:$AF$156,MATCH($U33,$A$6:$A$156,0)),WorkDays,1)+IF($Q33=0,0,1)+$W33))))) -> 46126 | AF33: =IF($AB33<>"",$AB33,IF($Q33=0,$AE33,INDEX(WorkDays,MATCH(MAX($AE33,NextWD)-1,WorkDays,1)+$AD33))) -> 46162 | AG33: =IF($AB33<>"","Completed",IF($AA33<>"","In Progress",IF(AND($Y33<>"",$Y33<=DataDate),"Not Started (Late)","Not Started"))) -> Completed | AH33: =IF($Z33="","",MATCH($AF33,WorkDays,1)-MATCH($Z33,WorkDays,1)) -> 7 | AI33: =IF($O33="","",$O33*IF($AB33<>"",1,$AC33)) | AJ33: Group actual dates = P6; split inside the group ASSUMED (sequenced) – replace with register / DPR dates.
A34: CHP-PRC-030 | B34: 4 | C34: PO placed – centrifugal chillers | D34: Procurement | H34: — (non-BIM milestone) | J34: =COUNTIF('BIM Element Map'!$J$6:$J$1000,$A34) -> 0 | L34: Milestone | N34: JSW USL-PR-2440 | Q34: 0 | R34: CHP-PRC-020 | S34: FS | T34: 0 | Y34: 46154 | Z34: 46154 | AA34: 46162 | AB34: 46162 | AC34: 1 | AD34: =IF($AB34<>"",0,IF($AA34="",$Q34,MAX(1,ROUND($Q34*(1-$AC34),0)))) -> 0 | AE34: =IF($AA34<>"",$AA34,MAX($X34,NextWD,IF($R34="",0,IF($S34="SS",INDEX(WorkDays,MATCH(INDEX($AE$6:$AE$156,MATCH($R34,$A$6:$A$156,0))-1,WorkDays,1)+1+$T34),INDEX(WorkDays,MATCH(INDEX($AF$6:$AF$156,MATCH($R34,$A$6:$A$156,0)),WorkDays,1)+IF($Q34=0,0,1)+$T34))),IF($U34="",0,IF($V34="SS",INDEX(WorkDays,MATCH(INDEX($AE$6:$AE$156,MATCH($U34,$A$6:$A$156,0))-1,WorkDays,1)+1+$W34),INDEX(WorkDays,MATCH(INDEX($AF$6:$AF$156,MATCH($U34,$A$6:$A$156,0)),WorkDays,1)+IF($Q34=0,0,1)+$W34))))) -> 46162 | AF34: =IF($AB34<>"",$AB34,IF($Q34=0,$AE34,INDEX(WorkDays,MATCH(MAX($AE34,NextWD)-1,WorkDays,1)+$AD34))) -> 46162 | AG34: =IF($AB34<>"","Completed",IF($AA34<>"","In Progress",IF(AND($Y34<>"",$Y34<=DataDate),"Not Started (Late)","Not Started"))) -> Completed | AH34: =IF($Z34="","",MATCH($AF34,WorkDays,1)-MATCH($Z34,WorkDays,1)) -> 7 | AI34: =IF($O34="","",$O34*IF($AB34<>"",1,$AC34)) | AJ34: Group actual dates = P6; split inside the group ASSUMED (sequenced) – replace with register / DPR dates.
A35: JSW USL-PR-2450 | B35: 3 | C35: Centrifugal Chillers - Manufacturing, Inspection & Delivery | J35: =SUMIF($B$36:$B$39,4,$J$36:$J$39) -> 0 | O35: =IF(SUMIF($B$36:$B$39,4,$O$36:$O$39)=0,"",SUMIF($B$36:$B$39,4,$O$36:$O$39)) | Y35: =MIN($Y$36:$Y$39) -> 46203 | Z35: =MAX($Z$36:$Z$39) -> 46380 | AA35: =IF(COUNT($AA$36:$AA$39)=0,"",MIN($AA$36:$AA$39)) -> 46164 | AB35: =IF(COUNTIFS($B$36:$B$39,4,$AG$36:$AG$39,"Completed")=COUNTIF($B$36:$B$39,4),MAX($AB$36:$AB$39),"") | AC35: =IFERROR(IF(SUMIF($B$36:$B$39,4,$O$36:$O$39)>0,SUMIF($B$36:$B$39,4,$AI$36:$AI$39)/SUMIF($B$36:$B$39,4,$O$36:$O$39),IFERROR(SUMPRODUCT(--($B$36:$B$39=4),$Q$36:$Q$39,$AC$36:$AC$39)/SUMIF($B$36:$B$39,4,$Q$36:$Q$39),AVERAGEIF($B$36:$B$39,4,$AC$36:$AC$39))),"") -> 0.60102128 | AE35: =MIN($AE$36:$AE$39) -> 46164 | AF35: =MAX($AF$36:$AF$39) -> 46387 | AG35: =IF(COUNTIFS($B$36:$B$39,4,$AG$36:$AG$39,"Completed")=COUNTIF($B$36:$B$39,4),"Completed",IF(COUNTIFS($B$36:$B$39,4,$AG$36:$AG$39,"Not Started*")=COUNTIF($B$36:$B$39,4),"Not Started","In Progress")) -> In Progress | AH35: =MATCH($AF35,WorkDays,1)-MATCH($Z35,WorkDays,1) -> 5 | AI35: =IF(SUMIF($B$36:$B$39,4,$O$36:$O$39)=0,"",SUMIF($B$36:$B$39,4,$AI$36:$AI$39)) | AJ35: ="P6 check: "&INDEX('P6 Roll-up'!$AB$5:$AB$22,MATCH($A35,'P6 Roll-up'!$A$5:$A$22,0)) -> P6 check: ✔ Same as P6
A36: CHP-PRC-040 | B36: 4 | C36: Centrifugal chillers – manufacturing | D36: Procurement | H36: — (non-BIM) | J36: =COUNTIF('BIM Element Map'!$J$6:$J$1000,$A36) -> 0 | L36: Construct | N36: JSW USL-PR-2450 | Q36: 165 | X36: 46164 | Y36: 46203 | Z36: 46359 | AA36: 46164 | AC36: 0.6848 | AD36: =IF($AB36<>"",0,IF($AA36="",$Q36,MAX(1,ROUND($Q36*(1-$AC36),0)))) -> 52 | AE36: =IF($AA36<>"",$AA36,MAX($X36,NextWD,IF($R36="",0,IF($S36="SS",INDEX(WorkDays,MATCH(INDEX($AE$6:$AE$156,MATCH($R36,$A$6:$A$156,0))-1,WorkDays,1)+1+$T36),INDEX(WorkDays,MATCH(INDEX($AF$6:$AF$156,MATCH($R36,$A$6:$A$156,0)),WorkDays,1)+IF($Q36=0,0,1)+$T36))),IF($U36="",0,IF($V36="SS",INDEX(WorkDays,MATCH(INDEX($AE$6:$AE$156,MATCH($U36,$A$6:$A$156,0))-1,WorkDays,1)+1+$W36),INDEX(WorkDays,MATCH(INDEX($AF$6:$AF$156,MATCH($U36,$A$6:$A$156,0)),WorkDays,1)+IF($Q36=0,0,1)+$W36))))) -> 46164 | AF36: =IF($AB36<>"",$AB36,IF($Q36=0,$AE36,INDEX(WorkDays,MATCH(MAX($AE36,NextWD)-1,WorkDays,1)+$AD36))) -> 46359 | AG36: =IF($AB36<>"","Completed",IF($AA36<>"","In Progress",IF(AND($Y36<>"",$Y36<=DataDate),"Not Started (Late)","Not Started"))) -> In Progress | AH36: =IF($Z36="","",MATCH($AF36,WorkDays,1)-MATCH($Z36,WorkDays,1)) -> 0 | AI36: =IF($O36="","",$O36*IF($AB36<>"",1,$AC36)) | AJ36: Group actual dates = P6; split inside the group ASSUMED (sequenced) – replace with register / DPR dates. In progress at DD; remaining duration set so the group finishes on the P6 date.
A37: CHP-PRC-050 | B37: 4 | C37: Centrifugal chillers – stage inspection & FAT | D37: Procurement | H37: — (non-BIM) | J37: =COUNTIF('BIM Element Map'!$J$6:$J$1000,$A37) -> 0 | L37: Construct | N37: JSW USL-PR-2450 | Q37: 8 | R37: CHP-PRC-040 | S37: FS | T37: 0 | Y37: 46360 | Z37: 46366 | AC37: 0 | AD37: =IF($AB37<>"",0,IF($AA37="",$Q37,MAX(1,ROUND($Q37*(1-$AC37),0)))) -> 8 | AE37: =IF($AA37<>"",$AA37,MAX($X37,NextWD,IF($R37="",0,IF($S37="SS",INDEX(WorkDays,MATCH(INDEX($AE$6:$AE$156,MATCH($R37,$A$6:$A$156,0))-1,WorkDays,1)+1+$T37),INDEX(WorkDays,MATCH(INDEX($AF$6:$AF$156,MATCH($R37,$A$6:$A$156,0)),WorkDays,1)+IF($Q37=0,0,1)+$T37))),IF($U37="",0,IF($V37="SS",INDEX(WorkDays,MATCH(INDEX($AE$6:$AE$156,MATCH($U37,$A$6:$A$156,0))-1,WorkDays,1)+1+$W37),INDEX(WorkDays,MATCH(INDEX($AF$6:$AF$156,MATCH($U37,$A$6:$A$156,0)),WorkDays,1)+IF($Q37=0,0,1)+$W37))))) -> 46360 | AF37: =IF($AB37<>"",$AB37,IF($Q37=0,$AE37,INDEX(WorkDays,MATCH(MAX($AE37,NextWD)-1,WorkDays,1)+$AD37))) -> 46368 | AG37: =IF($AB37<>"","Completed",IF($AA37<>"","In Progress",IF(AND($Y37<>"",$Y37<=DataDate),"Not Started (Late)","Not Started"))) -> Not Started | AH37: =IF($Z37="","",MATCH($AF37,WorkDays,1)-MATCH($Z37,WorkDays,1)) -> 2 | AI37: =IF($O37="","",$O37*IF($AB37<>"",1,$AC37)) | AJ37: Sequenced to finish on P6 date 31-Dec-26.
A38: CHP-PRC-060 | B38: 4 | C38: Centrifugal chillers – dispatch & transit to site | D38: Procurement | H38: — (non-BIM) | J38: =COUNTIF('BIM Element Map'!$J$6:$J$1000,$A38) -> 0 | L38: Construct | N38: JSW USL-PR-2450 | Q38: 15 | R38: CHP-PRC-050 | S38: FS | T38: 0 | Y38: 46367 | Z38: 46380 | AC38: 0 | AD38: =IF($AB38<>"",0,IF($AA38="",$Q38,MAX(1,ROUND($Q38*(1-$AC38),0)))) -> 15 | AE38: =IF($AA38<>"",$AA38,MAX($X38,NextWD,IF($R38="",0,IF($S38="SS",INDEX(WorkDays,MATCH(INDEX($AE$6:$AE$156,MATCH($R38,$A$6:$A$156,0))-1,WorkDays,1)+1+$T38),INDEX(WorkDays,MATCH(INDEX($AF$6:$AF$156,MATCH($R38,$A$6:$A$156,0)),WorkDays,1)+IF($Q38=0,0,1)+$T38))),IF($U38="",0,IF($V38="SS",INDEX(WorkDays,MATCH(INDEX($AE$6:$AE$156,MATCH($U38,$A$6:$A$156,0))-1,WorkDays,1)+1+$W38),INDEX(WorkDays,MATCH(INDEX($AF$6:$AF$156,MATCH($U38,$A$6:$A$156,0)),WorkDays,1)+IF($Q38=0,0,1)+$W38))))) -> 46370 | AF38: =IF($AB38<>"",$AB38,IF($Q38=0,$AE38,INDEX(WorkDays,MATCH(MAX($AE38,NextWD)-1,WorkDays,1)+$AD38))) -> 46387 | AG38: =IF($AB38<>"","Completed",IF($AA38<>"","In Progress",IF(AND($Y38<>"",$Y38<=DataDate),"Not Started (Late)","Not Started"))) -> Not Started | AH38: =IF($Z38="","",MATCH($AF38,WorkDays,1)-MATCH($Z38,WorkDays,1)) -> 5 | AI38: =IF($O38="","",$O38*IF($AB38<>"",1,$AC38)) | AJ38: Sequenced to finish on P6 date 31-Dec-26.
A39: CHP-MS-070 | B39: 4 | C39: Centrifugal chillers delivered at site | D39: Milestone | H39: — (non-BIM milestone) | J39: =COUNTIF('BIM Element Map'!$J$6:$J$1000,$A39) -> 0 | L39: Milestone | N39: JSW USL-PR-2450 | Q39: 0 | R39: CHP-PRC-060 | S39: FS | T39: 0 | Y39: 46380 | Z39: 46380 | AC39: 0 | AD39: =IF($AB39<>"",0,IF($AA39="",$Q39,MAX(1,ROUND($Q39*(1-$AC39),0)))) -> 0 | AE39: =IF($AA39<>"",$AA39,MAX($X39,NextWD,IF($R39="",0,IF($S39="SS",INDEX(WorkDays,MATCH(INDEX($AE$6:$AE$156,MATCH($R39,$A$6:$A$156,0))-1,WorkDays,1)+1+$T39),INDEX(WorkDays,MATCH(INDEX($AF$6:$AF$156,MATCH($R39,$A$6:$A$156,0)),WorkDays,1)+IF($Q39=0,0,1)+$T39))),IF($U39="",0,IF($V39="SS",INDEX(WorkDays,MATCH(INDEX($AE$6:$AE$156,MATCH($U39,$A$6:$A$156,0))-1,WorkDays,1)+1+$W39),INDEX(WorkDays,MATCH(INDEX($AF$6:$AF$156,MATCH($U39,$A$6:$A$156,0)),WorkDays,1)+IF($Q39=0,0,1)+$W39))))) -> 46387 | AF39: =IF($AB39<>"",$AB39,IF($Q39=0,$AE39,INDEX(WorkDays,MATCH(MAX($AE39,NextWD)-1,WorkDays,1)+$AD39))) -> 46387 | AG39: =IF($AB39<>"","Completed",IF($AA39<>"","In Progress",IF(AND($Y39<>"",$Y39<=DataDate),"Not Started (Late)","Not Started"))) -> Not Started | AH39: =IF($Z39="","",MATCH($AF39,WorkDays,1)-MATCH($Z39,WorkDays,1)) -> 5 | AI39: =IF($O39="","",$O39*IF($AB39<>"",1,$AC39)) | AJ39: Sequenced to finish on P6 date 31-Dec-26.
A40: JSW USL-PR-2460 | B40: 3 | C40: Pumps - PR to PO | J40: =SUMIF($B$41:$B$43,4,$J$41:$J$43) -> 0 | O40: =IF(SUMIF($B$41:$B$43,4,$O$41:$O$43)=0,"",SUMIF($B$41:$B$43,4,$O$41:$O$43)) | Y40: =MIN($Y$41:$Y$43) -> 46081 | Z40: =MAX($Z$41:$Z$43) -> 46154 | AA40: =IF(COUNT($AA$41:$AA$43)=0,"",MIN($AA$41:$AA$43)) -> 46056 | AB40: =IF(COUNTIFS($B$41:$B$43,4,$AG$41:$AG$43,"Completed")=COUNTIF($B$41:$B$43,4),MAX($AB$41:$AB$43),"") -> 46139 | AC40: =IFERROR(IF(SUMIF($B$41:$B$43,4,$O$41:$O$43)>0,SUMIF($B$41:$B$43,4,$AI$41:$AI$43)/SUMIF($B$41:$B$43,4,$O$41:$O$43),IFERROR(SUMPRODUCT(--($B$41:$B$43=4),$Q$41:$Q$43,$AC$41:$AC$43)/SUMIF($B$41:$B$43,4,$Q$41:$Q$43),AVERAGEIF($B$41:$B$43,4,$AC$41:$AC$43))),"") -> 1 | AE40: =MIN($AE$41:$AE$43) -> 46056 | AF40: =MAX($AF$41:$AF$43) -> 46139 | AG40: =IF(COUNTIFS($B$41:$B$43,4,$AG$41:$AG$43,"Completed")=COUNTIF($B$41:$B$43,4),"Completed",IF(COUNTIFS($B$41:$B$43,4,$AG$41:$AG$43,"Not Started*")=COUNTIF($B$41:$B$43,4),"Not Started","In Progress")) -> Completed | AH40: =MATCH($AF40,WorkDays,1)-MATCH($Z40,WorkDays,1) -> -12 | AI40: =IF(SUMIF($B$41:$B$43,4,$O$41:$O$43)=0,"",SUMIF($B$41:$B$43,4,$AI$41:$AI$43)) | AJ40: ="P6 check: "&INDEX('P6 Roll-up'!$AB$5:$AB$22,MATCH($A40,'P6 Roll-up'!$A$5:$A$22,0)) -> P6 check: ✔ Same as P6
...

Sheet BIM Element Map
A1: BIM ELEMENT MAP – element → 4D activity link (Chiller Plant)
A2: Use: add two shared/text parameters in the model (4D_Element_ID, 4D_Activity_ID) and populate them from columns A and J (Dynamo / Excel link / Navisworks property append). Then in TimeLiner use Rules to attach by 4D_Activity_ID.
A3: Columns K–N are live look-ups from the 4D Schedule. Columns are split at construction joints (EL -0.300, +4.000, +9.150) – split model columns the same way, or attach a full-height column to its first lift only.
A5: Element ID (suggested 4D_Element_ID) | B5: BIM Category | C5: Element Type / Description | D5: Mark | E5: Grid / Location | F5: Zone | G5: Level / Elevation | H5: Size | I5: Drawing No. | J5: 4D Activity ID (4D_Activity_ID) | K5: Activity Name | L5: Current Start | M5: Current Finish | N5: Status | O5: Notes
A6: CHP-PILE-P01 | B6: Structural Foundations (Pile) | C6: Bored cast-in-situ pile, Type-I, M30 | D6: P1 | E6: 1/A | F6: Z1 | G6: Cut-off EL(-)2.425 ; L = 26 m | H6: 600 Ø | I6: O24091-990-C-B-19530-001 | J6: CHP-PIL-010 | K6: =INDEX('4D Schedule'!$C$6:$C$156,MATCH($J6,'4D Schedule'!$A$6:$A$156,0)) -> Piles Row A (P1–P7) | L6: =INDEX('4D Schedule'!$AE$6:$AE$156,MATCH($J6,'4D Schedule'!$A$6:$A$156,0)) -> 46008 | M6: =INDEX('4D Schedule'!$AF$6:$AF$156,MATCH($J6,'4D Schedule'!$A$6:$A$156,0)) -> 46011 | N6: =INDEX('4D Schedule'!$AG$6:$AG$156,MATCH($J6,'4D Schedule'!$A$6:$A$156,0)) -> Completed
A7: CHP-PILE-P02 | B7: Structural Foundations (Pile) | C7: Bored cast-in-situ pile, Type-I, M30 | D7: P2 | E7: 2/A | F7: Z1 | G7: Cut-off EL(-)2.425 ; L = 26 m | H7: 600 Ø | I7: O24091-990-C-B-19530-001 | J7: CHP-PIL-010 | K7: =INDEX('4D Schedule'!$C$6:$C$156,MATCH($J7,'4D Schedule'!$A$6:$A$156,0)) -> Piles Row A (P1–P7) | L7: =INDEX('4D Schedule'!$AE$6:$AE$156,MATCH($J7,'4D Schedule'!$A$6:$A$156,0)) -> 46008 | M7: =INDEX('4D Schedule'!$AF$6:$AF$156,MATCH($J7,'4D Schedule'!$A$6:$A$156,0)) -> 46011 | N7: =INDEX('4D Schedule'!$AG$6:$AG$156,MATCH($J7,'4D Schedule'!$A$6:$A$156,0)) -> Completed
A8: CHP-PILE-P03 | B8: Structural Foundations (Pile) | C8: Bored cast-in-situ pile, Type-I, M30 | D8: P3 | E8: 3/A | F8: Z1 | G8: Cut-off EL(-)2.425 ; L = 26 m | H8: 600 Ø | I8: O24091-990-C-B-19530-001 | J8: CHP-PIL-010 | K8: =INDEX('4D Schedule'!$C$6:$C$156,MATCH($J8,'4D Schedule'!$A$6:$A$156,0)) -> Piles Row A (P1–P7) | L8: =INDEX('4D Schedule'!$AE$6:$AE$156,MATCH($J8,'4D Schedule'!$A$6:$A$156,0)) -> 46008 | M8: =INDEX('4D Schedule'!$AF$6:$AF$156,MATCH($J8,'4D Schedule'!$A$6:$A$156,0)) -> 46011 | N8: =INDEX('4D Schedule'!$AG$6:$AG$156,MATCH($J8,'4D Schedule'!$A$6:$A$156,0)) -> Completed
A9: CHP-PILE-P04 | B9: Structural Foundations (Pile) | C9: Bored cast-in-situ pile, Type-I, M30 | D9: P4 | E9: 4/A | F9: Z2 | G9: Cut-off EL(-)2.425 ; L = 26 m | H9: 600 Ø | I9: O24091-990-C-B-19530-001 | J9: CHP-PIL-010 | K9: =INDEX('4D Schedule'!$C$6:$C$156,MATCH($J9,'4D Schedule'!$A$6:$A$156,0)) -> Piles Row A (P1–P7) | L9: =INDEX('4D Schedule'!$AE$6:$AE$156,MATCH($J9,'4D Schedule'!$A$6:$A$156,0)) -> 46008 | M9: =INDEX('4D Schedule'!$AF$6:$AF$156,MATCH($J9,'4D Schedule'!$A$6:$A$156,0)) -> 46011 | N9: =INDEX('4D Schedule'!$AG$6:$AG$156,MATCH($J9,'4D Schedule'!$A$6:$A$156,0)) -> Completed
A10: CHP-PILE-P05 | B10: Structural Foundations (Pile) | C10: Bored cast-in-situ pile, Type-I, M30 | D10: P5 | E10: 5/A | F10: Z2 | G10: Cut-off EL(-)2.425 ; L = 26 m | H10: 600 Ø | I10: O24091-990-C-B-19530-001 | J10: CHP-PIL-010 | K10: =INDEX('4D Schedule'!$C$6:$C$156,MATCH($J10,'4D Schedule'!$A$6:$A$156,0)) -> Piles Row A (P1–P7) | L10: =INDEX('4D Schedule'!$AE$6:$AE$156,MATCH($J10,'4D Schedule'!$A$6:$A$156,0)) -> 46008 | M10: =INDEX('4D Schedule'!$AF$6:$AF$156,MATCH($J10,'4D Schedule'!$A$6:$A$156,0)) -> 46011 | N10: =INDEX('4D Schedule'!$AG$6:$AG$156,MATCH($J10,'4D Schedule'!$A$6:$A$156,0)) -> Completed
A11: CHP-PILE-P06 | B11: Structural Foundations (Pile) | C11: Bored cast-in-situ pile, Type-I, M30 | D11: P6 | E11: 5/A | F11: Z2 | G11: Cut-off EL(-)2.425 ; L = 26 m | H11: 600 Ø | I11: O24091-990-C-B-19530-001 | J11: CHP-PIL-010 | K11: =INDEX('4D Schedule'!$C$6:$C$156,MATCH($J11,'4D Schedule'!$A$6:$A$156,0)) -> Piles Row A (P1–P7) | L11: =INDEX('4D Schedule'!$AE$6:$AE$156,MATCH($J11,'4D Schedule'!$A$6:$A$156,0)) -> 46008 | M11: =INDEX('4D Schedule'!$AF$6:$AF$156,MATCH($J11,'4D Schedule'!$A$6:$A$156,0)) -> 46011 | N11: =INDEX('4D Schedule'!$AG$6:$AG$156,MATCH($J11,'4D Schedule'!$A$6:$A$156,0)) -> Completed
A12: CHP-PILE-P07 | B12: Structural Foundations (Pile) | C12: Bored cast-in-situ pile, Type-I, M30 | D12: P7 | E12: 6/A | F12: Z3 | G12: Cut-off EL(-)2.425 ; L = 26 m | H12: 600 Ø | I12: O24091-990-C-B-19530-001 | J12: CHP-PIL-010 | K12: =INDEX('4D Schedule'!$C$6:$C$156,MATCH($J12,'4D Schedule'!$A$6:$A$156,0)) -> Piles Row A (P1–P7) | L12: =INDEX('4D Schedule'!$AE$6:$AE$156,MATCH($J12,'4D Schedule'!$A$6:$A$156,0)) -> 46008 | M12: =INDEX('4D Schedule'!$AF$6:$AF$156,MATCH($J12,'4D Schedule'!$A$6:$A$156,0)) -> 46011 | N12: =INDEX('4D Schedule'!$AG$6:$AG$156,MATCH($J12,'4D Schedule'!$A$6:$A$156,0)) -> Completed
A13: CHP-PILE-P08 | B13: Structural Foundations (Pile) | C13: Bored cast-in-situ pile, Type-I, M30 | D13: P8 | E13: 1/B | F13: Z1 | G13: Cut-off EL(-)2.425 ; L = 26 m | H13: 600 Ø | I13: O24091-990-C-B-19530-001 | J13: CHP-PIL-020 | K13: =INDEX('4D Schedule'!$C$6:$C$156,MATCH($J13,'4D Schedule'!$A$6:$A$156,0)) -> Piles Row B (P8–P16) | L13: =INDEX('4D Schedule'!$AE$6:$AE$156,MATCH($J13,'4D Schedule'!$A$6:$A$156,0)) -> 46013 | M13: =INDEX('4D Schedule'!$AF$6:$AF$156,MATCH($J13,'4D Schedule'!$A$6:$A$156,0)) -> 46018 | N13: =INDEX('4D Schedule'!$AG$6:$AG$156,MATCH($J13,'4D Schedule'!$A$6:$A$156,0)) -> Completed
A14: CHP-PILE-P09 | B14: Structural Foundations (Pile) | C14: Bored cast-in-situ pile, Type-I, M30 | D14: P9 | E14: 1/B | F14: Z1 | G14: Cut-off EL(-)2.425 ; L = 26 m | H14: 600 Ø | I14: O24091-990-C-B-19530-001 | J14: CHP-PIL-020 | K14: =INDEX('4D Schedule'!$C$6:$C$156,MATCH($J14,'4D Schedule'!$A$6:$A$156,0)) -> Piles Row B (P8–P16) | L14: =INDEX('4D Schedule'!$AE$6:$AE$156,MATCH($J14,'4D Schedule'!$A$6:$A$156,0)) -> 46013 | M14: =INDEX('4D Schedule'!$AF$6:$AF$156,MATCH($J14,'4D Schedule'!$A$6:$A$156,0)) -> 46018 | N14: =INDEX('4D Schedule'!$AG$6:$AG$156,MATCH($J14,'4D Schedule'!$A$6:$A$156,0)) -> Completed
A15: CHP-PILE-P10 | B15: Structural Foundations (Pile) | C15: Bored cast-in-situ pile, Type-I, M30 | D15: P10 | E15: 2/B | F15: Z1 | G15: Cut-off EL(-)2.425 ; L = 26 m | H15: 600 Ø | I15: O24091-990-C-B-19530-001 | J15: CHP-PIL-020 | K15: =INDEX('4D Schedule'!$C$6:$C$156,MATCH($J15,'4D Schedule'!$A$6:$A$156,0)) -> Piles Row B (P8–P16) | L15: =INDEX('4D Schedule'!$AE$6:$AE$156,MATCH($J15,'4D Schedule'!$A$6:$A$156,0)) -> 46013 | M15: =INDEX('4D Schedule'!$AF$6:$AF$156,MATCH($J15,'4D Schedule'!$A$6:$A$156,0)) -> 46018 | N15: =INDEX('4D Schedule'!$AG$6:$AG$156,MATCH($J15,'4D Schedule'!$A$6:$A$156,0)) -> Completed
